Workbook
Name IndustryList: 設定!$A$6:$A$7
Name SL_業種: #N/A
Name SL_商品: #N/A
Name TL_日付: #N/A

Sheet 採算シミュレーション
A2: 見積・原価・利益シミュレーター
A5: 対象業種 | B5: 木工所 | D5: 試算売上 | G5: 試算原価
D6: =計算!B30 -> 160000 | G6: =計算!B31 -> 88000
A7: 目標利益率 | B7: 0.3
A9: 試算値引率(%) | B9: 0 | D9: 予定案件利益 | G9: 予定案件利益率
D10: =計算!B32 -> 72000 | G10: =計算!B33 -> 0.45
A11: 原価増減率 | B11: 0
D12: =IF(計算!B10<>"OK",計算!B10,IF(計算!B30=0,"売価0円・利益率算出不可",IF(計算!B32<0,"赤字",IF(計算!B33<B7,"黒字・目標未達","目標達成")))) -> 目標達成
A13: 原価増減率は原価全体への一律試算です。個別条件・数量変更は見積入力と業種別原価シートで行います。
A15: 試算値引率は見積書に反映されません。採用する率を「見積入力」の確定値引率へ入力してください。
A17: 目標必要売価 | B17: =計算!B34 -> 125715 | D17: 目標維持値引上限 | F17: =計算!B35 -> 0.21428125 | G17: 共通経費 | H17: =計算!B11 -> 今回は未算入
A35: 明細ID | B35: 品名 | C35: 試算売上 | D35: 紐付く原価 | E35: 共通費控除前差額 | F35: 同利益率
A36: =計算!A16 -> M001 | B36: =計算!B16 -> テーブル | C36: =計算!F16 -> 100000 | D36: =計算!G16 -> 50000 | E36: =IF(OR(A36="",計算!B10<>"OK"),"",C36-D36) -> 50000 | F36: =IF(OR(A36="",計算!B10<>"OK"),"",IF(C36=0,"算出不可",E36/C36)) -> 0.5
A37: =計算!A17 -> M002 | B37: =計算!B17 -> 椅子 | C37: =計算!F17 -> 60000 | D37: =計算!G17 -> 30000 | E37: =IF(OR(A37="",計算!B10<>"OK"),"",C37-D37) -> 30000 | F37: =IF(OR(A37="",計算!B10<>"OK"),"",IF(C37=0,"算出不可",E37/C37)) -> 0.5
A38: =計算!A18 | B38: =計算!B18 | C38: =計算!F18 | D38: =計算!G18 | E38: =IF(OR(A38="",計算!B10<>"OK"),"",C38-D38) | F38: =IF(OR(A38="",計算!B10<>"OK"),"",IF(C38=0,"算出不可",E38/C38))
A39: =計算!A19 | B39: =計算!B19 | C39: =計算!F19 | D39: =計算!G19 | E39: =IF(OR(A39="",計算!B10<>"OK"),"",C39-D39) | F39: =IF(OR(A39="",計算!B10<>"OK"),"",IF(C39=0,"算出不可",E39/C39))
A40: =計算!A20 | B40: =計算!B20 | C40: =計算!F20 | D40: =計算!G20 | E40: =IF(OR(A40="",計算!B10<>"OK"),"",C40-D40) | F40: =IF(OR(A40="",計算!B10<>"OK"),"",IF(C40=0,"算出不可",E40/C40))
A41: =計算!A21 | B41: =計算!B21 | C41: =計算!F21 | D41: =計算!G21 | E41: =IF(OR(A41="",計算!B10<>"OK"),"",C41-D41) | F41: =IF(OR(A41="",計算!B10<>"OK"),"",IF(C41=0,"算出不可",E41/C41))
A42: =計算!A22 | B42: =計算!B22 | C42: =計算!F22 | D42: =計算!G22 | E42: =IF(OR(A42="",計算!B10<>"OK"),"",C42-D42) | F42: =IF(OR(A42="",計算!B10<>"OK"),"",IF(C42=0,"算出不可",E42/C42))
A43: =計算!A23 | B43: =計算!B23 | C43: =計算!F23 | D43: =計算!G23 | E43: =IF(OR(A43="",計算!B10<>"OK"),"",C43-D43) | F43: =IF(OR(A43="",計算!B10<>"OK"),"",IF(C43=0,"算出不可",E43/C43))
A44: =計算!A24 | B44: =計算!B24 | C44: =計算!F24 | D44: =計算!G24 | E44: =IF(OR(A44="",計算!B10<>"OK"),"",C44-D44) | F44: =IF(OR(A44="",計算!B10<>"OK"),"",IF(C44=0,"算出不可",E44/C44))
A45: =計算!A25 | B45: =計算!B25 | C45: =計算!F25 | D45: =計算!G25 | E45: =IF(OR(A45="",計算!B10<>"OK"),"",C45-D45) | F45: =IF(OR(A45="",計算!B10<>"OK"),"",IF(C45=0,"算出不可",E45/C45))
A47: 案件共通費 | D47: =計算!B41 -> 8000
A49: 商品別の差額は案件共通費の控除前です。案件全体の予定利益は共通費を差し引いた結果です。

Sheet 見積書
A2: 見積書
A4: =見積入力!B6&" 御中" -> サンプルのお客様 御中 | G4: ="見積番号："&見積入力!B7 -> 見積番号：DEMO-001
G5: =設定!B11 -> サンプル事業者
A6: ="件名："&見積入力!B5 -> 件名：家具製作・納品 | G6: =設定!B12 -> 住所を入力してください
G7: =設定!B13 -> 連絡先を入力してください
A8: 税込見積金額 | C8: =IF(計算!B10="OK",計算!B39,"入力を確認") -> 176000
G9: ="有効期限："&見積入力!B10 -> 有効期限：発行日から30日
A11: 発行日 | B11: =見積入力!B9 -> 46315
A13: No. | B13: 品名 | C13: 規格・仕様 | D13: 数量 | E13: 単位 | F13: 税抜単価 | G13: 値引前金額 | H13: 値引額 | I13: 税抜金額 | J13: 税率
A14: =IF(計算!A16="","",1) -> 1 | B14: =IF(A14="","",見積入力!B16) -> テーブル | C14: =IF(A14="","",見積入力!C16) -> 標準仕様 | D14: =IF(A14="","",見積入力!D16) -> 2 | E14: =IF(A14="","",見積入力!E16) -> 台 | F14: =IF(A14="","",見積入力!F16) -> 50000 | G14: =IF(A14="","",見積入力!H16) -> 100000 | H14: =IF(OR(A14="",計算!B10<>"OK"),"",G14-I14) -> 0 | I14: =IF(A14="","",計算!H16) -> 100000 | J14: =IF(A14="","",見積入力!G16) -> 0.1
A15: =IF(計算!A17="","",2) -> 2 | B15: =IF(A15="","",見積入力!B17) -> 椅子 | C15: =IF(A15="","",見積入力!C17) -> 標準仕様 | D15: =IF(A15="","",見積入力!D17) -> 4 | E15: =IF(A15="","",見積入力!E17) -> 脚 | F15: =IF(A15="","",見積入力!F17) -> 15000 | G15: =IF(A15="","",見積入力!H17) -> 60000 | H15: =IF(OR(A15="",計算!B10<>"OK"),"",G15-I15) -> 0 | I15: =IF(A15="","",計算!H17) -> 60000 | J15: =IF(A15="","",見積入力!G17) -> 0.1
A16: =IF(計算!A18="","",3) | B16: =IF(A16="","",見積入力!B18) | C16: =IF(A16="","",見積入力!C18) | D16: =IF(A16="","",見積入力!D18) | E16: =IF(A16="","",見積入力!E18) | F16: =IF(A16="","",見積入力!F18) | G16: =IF(A16="","",見積入力!H18) | H16: =IF(OR(A16="",計算!B10<>"OK"),"",G16-I16) | I16: =IF(A16="","",計算!H18) | J16: =IF(A16="","",見積入力!G18)
A17: =IF(計算!A19="","",4) | B17: =IF(A17="","",見積入力!B19) | C17: =IF(A17="","",見積入力!C19) | D17: =IF(A17="","",見積入力!D19) | E17: =IF(A17="","",見積入力!E19) | F17: =IF(A17="","",見積入力!F19) | G17: =IF(A17="","",見積入力!H19) | H17: =IF(OR(A17="",計算!B10<>"OK"),"",G17-I17) | I17: =IF(A17="","",計算!H19) | J17: =IF(A17="","",見積入力!G19)
A18: =IF(計算!A20="","",5) | B18: =IF(A18="","",見積入力!B20) | C18: =IF(A18="","",見積入力!C20) | D18: =IF(A18="","",見積入力!D20) | E18: =IF(A18="","",見積入力!E20) | F18: =IF(A18="","",見積入力!F20) | G18: =IF(A18="","",見積入力!H20) | H18: =IF(OR(A18="",計算!B10<>"OK"),"",G18-I18) | I18: =IF(A18="","",計算!H20) | J18: =IF(A18="","",見積入力!G20)
A19: =IF(計算!A21="","",6) | B19: =IF(A19="","",見積入力!B21) | C19: =IF(A19="","",見積入力!C21) | D19: =IF(A19="","",見積入力!D21) | E19: =IF(A19="","",見積入力!E21) | F19: =IF(A19="","",見積入力!F21) | G19: =IF(A19="","",見積入力!H21) | H19: =IF(OR(A19="",計算!B10<>"OK"),"",G19-I19) | I19: =IF(A19="","",計算!H21) | J19: =IF(A19="","",見積入力!G21)
A20: =IF(計算!A22="","",7) | B20: =IF(A20="","",見積入力!B22) | C20: =IF(A20="","",見積入力!C22) | D20: =IF(A20="","",見積入力!D22) | E20: =IF(A20="","",見積入力!E22) | F20: =IF(A20="","",見積入力!F22) | G20: =IF(A20="","",見積入力!H22) | H20: =IF(OR(A20="",計算!B10<>"OK"),"",G20-I20) | I20: =IF(A20="","",計算!H22) | J20: =IF(A20="","",見積入力!G22)
A21: =IF(計算!A23="","",8) | B21: =IF(A21="","",見積入力!B23) | C21: =IF(A21="","",見積入力!C23) | D21: =IF(A21="","",見積入力!D23) | E21: =IF(A21="","",見積入力!E23) | F21: =IF(A21="","",見積入力!F23) | G21: =IF(A21="","",見積入力!H23) | H21: =IF(OR(A21="",計算!B10<>"OK"),"",G21-I21) | I21: =IF(A21="","",計算!H23) | J21: =IF(A21="","",見積入力!G23)
A22: =IF(計算!A24="","",9) | B22: =IF(A22="","",見積入力!B24) | C22: =IF(A22="","",見積入力!C24) | D22: =IF(A22="","",見積入力!D24) | E22: =IF(A22="","",見積入力!E24) | F22: =IF(A22="","",見積入力!F24) | G22: =IF(A22="","",見積入力!H24) | H22: =IF(OR(A22="",計算!B10<>"OK"),"",G22-I22) | I22: =IF(A22="","",計算!H24) | J22: =IF(A22="","",見積入力!G24)
A23: =IF(計算!A25="","",10) | B23: =IF(A23="","",見積入力!B25) | C23: =IF(A23="","",見積入力!C25) | D23: =IF(A23="","",見積入力!D25) | E23: =IF(A23="","",見積入力!E25) | F23: =IF(A23="","",見積入力!F25) | G23: =IF(A23="","",見積入力!H25) | H23: =IF(OR(A23="",計算!B10<>"OK"),"",G23-I23) | I23: =IF(A23="","",計算!H25) | J23: =IF(A23="","",見積入力!G25)
A25: ="納期・支払条件："&見積入力!B11 -> 納期・支払条件：納期・支払条件を入力 | G25: 税抜合計 | I25: =IF(計算!B10="OK",計算!B36,"") -> 160000
G26: 10%対象額 | I26: =IF(計算!B10="OK",SUMIFS(計算!H16:H25,計算!I16:I25,0.1),"") -> 160000
G27: 10%消費税 | I27: =IF(計算!B10="OK",計算!B37,"") -> 16000
A28: ="備考："&見積入力!B12 -> 備考：試作品の架空データです | G28: 8%対象額 | I28: =IF(計算!B10="OK",SUMIFS(計算!H16:H25,計算!I16:I25,0.08),"") -> 0
G29: 8%消費税 | I29: =IF(計算!B10="OK",計算!B38,"") -> 0
G30: 税込合計 | I30: =IF(計算!B10="OK",計算!B39,"") -> 176000
A32: =IF(計算!B10<>"OK","発行不可："&計算!B10,IF(OR(見積入力!B5="",見積入力!B6="",見積入力!B7="",設定!B11=""),"宛先・件名・番号・自社名を確認",""))
A34: 8%対象・10%対象の税額はそれぞれ円未満切捨て。0%入力分は税額0円として集計。

Sheet 見積入力
A2: 見積入力
A5: 件名 | B5: 家具製作・納品
A6: 宛先 | B6: サンプルのお客様
A7: 見積番号 | B7: DEMO-001
A8: 確定値引率 | B8: 0
A9: 発行日 | B9: 46315
A10: 有効期限 | B10: 発行日から30日
A11: 納期・支払条件 | B11: 納期・支払条件を入力
A12: 備考 | B12: 試作品の架空データです
A15: 明細ID | B15: 品名 | C15: 規格・仕様 | D15: 数量 | E15: 単位 | F15: 税抜単価 | G15: 税率 | H15: 税抜金額 | I15: 入力確認
A16: M001 | B16: テーブル | C16: 標準仕様 | D16: 2 | E16: 台 | F16: 50000 | G16: 0.1 | H16: =IF(I16="OK",ROUND(D16*F16,0),"") -> 100000 | I16: =IF(OR(A16="案件共通",ISNUMBER(SEARCH("~*",A16)),ISNUMBER(SEARCH("~?",A16)),ISNUMBER(SEARCH("~~",A16))),"IDに予約語・特殊文字不可",IF(COUNTA(A16:G16)=0,"",IF(OR(A16="",B16="",E16=""),"必須欄不足",IF(COUNTIFS($A$16:$A$25,A16)<>1,"ID重複",IF(OR(NOT(ISNUMBER(D16)),NOT(ISNUMBER(F16)),NOT(ISNUMBER(G16))),"数値を入力",IF(OR(D16<=0,F16<0,AND(G16<>0,G16<>0.08,G16<>0.1)),"数量・価格・税率確認","OK")))))) -> OK
A17: M002 | B17: 椅子 | C17: 標準仕様 | D17: 4 | E17: 脚 | F17: 15000 | G17: 0.1 | H17: =IF(I17="OK",ROUND(D17*F17,0),"") -> 60000 | I17: =IF(OR(A17="案件共通",ISNUMBER(SEARCH("~*",A17)),ISNUMBER(SEARCH("~?",A17)),ISNUMBER(SEARCH("~~",A17))),"IDに予約語・特殊文字不可",IF(COUNTA(A17:G17)=0,"",IF(OR(A17="",B17="",E17=""),"必須欄不足",IF(COUNTIFS($A$16:$A$25,A17)<>1,"ID重複",IF(OR(NOT(ISNUMBER(D17)),NOT(ISNUMBER(F17)),NOT(ISNUMBER(G17))),"数値を入力",IF(OR(D17<=0,F17<0,AND(G17<>0,G17<>0.08,G17<>0.1)),"数量・価格・税率確認","OK")))))) -> OK
H18: =IF(I18="OK",ROUND(D18*F18,0),"") | I18: =IF(OR(A18="案件共通",ISNUMBER(SEARCH("~*",A18)),ISNUMBER(SEARCH("~?",A18)),ISNUMBER(SEARCH("~~",A18))),"IDに予約語・特殊文字不可",IF(COUNTA(A18:G18)=0,"",IF(OR(A18="",B18="",E18=""),"必須欄不足",IF(COUNTIFS($A$16:$A$25,A18)<>1,"ID重複",IF(OR(NOT(ISNUMBER(D18)),NOT(ISNUMBER(F18)),NOT(ISNUMBER(G18))),"数値を入力",IF(OR(D18<=0,F18<0,AND(G18<>0,G18<>0.08,G18<>0.1)),"数量・価格・税率確認","OK"))))))
H19: =IF(I19="OK",ROUND(D19*F19,0),"") | I19: =IF(OR(A19="案件共通",ISNUMBER(SEARCH("~*",A19)),ISNUMBER(SEARCH("~?",A19)),ISNUMBER(SEARCH("~~",A19))),"IDに予約語・特殊文字不可",IF(COUNTA(A19:G19)=0,"",IF(OR(A19="",B19="",E19=""),"必須欄不足",IF(COUNTIFS($A$16:$A$25,A19)<>1,"ID重複",IF(OR(NOT(ISNUMBER(D19)),NOT(ISNUMBER(F19)),NOT(ISNUMBER(G19))),"数値を入力",IF(OR(D19<=0,F19<0,AND(G19<>0,G19<>0.08,G19<>0.1)),"数量・価格・税率確認","OK"))))))
H20: =IF(I20="OK",ROUND(D20*F20,0),"") | I20: =IF(OR(A20="案件共通",ISNUMBER(SEARCH("~*",A20)),ISNUMBER(SEARCH("~?",A20)),ISNUMBER(SEARCH("~~",A20))),"IDに予約語・特殊文字不可",IF(COUNTA(A20:G20)=0,"",IF(OR(A20="",B20="",E20=""),"必須欄不足",IF(COUNTIFS($A$16:$A$25,A20)<>1,"ID重複",IF(OR(NOT(ISNUMBER(D20)),NOT(ISNUMBER(F20)),NOT(ISNUMBER(G20))),"数値を入力",IF(OR(D20<=0,F20<0,AND(G20<>0,G20<>0.08,G20<>0.1)),"数量・価格・税率確認","OK"))))))
H21: =IF(I21="OK",ROUND(D21*F21,0),"") | I21: =IF(OR(A21="案件共通",ISNUMBER(SEARCH("~*",A21)),ISNUMBER(SEARCH("~?",A21)),ISNUMBER(SEARCH("~~",A21))),"IDに予約語・特殊文字不可",IF(COUNTA(A21:G21)=0,"",IF(OR(A21="",B21="",E21=""),"必須欄不足",IF(COUNTIFS($A$16:$A$25,A21)<>1,"ID重複",IF(OR(NOT(ISNUMBER(D21)),NOT(ISNUMBER(F21)),NOT(ISNUMBER(G21))),"数値を入力",IF(OR(D21<=0,F21<0,AND(G21<>0,G21<>0.08,G21<>0.1)),"数量・価格・税率確認","OK"))))))
H22: =IF(I22="OK",ROUND(D22*F22,0),"") | I22: =IF(OR(A22="案件共通",ISNUMBER(SEARCH("~*",A22)),ISNUMBER(SEARCH("~?",A22)),ISNUMBER(SEARCH("~~",A22))),"IDに予約語・特殊文字不可",IF(COUNTA(A22:G22)=0,"",IF(OR(A22="",B22="",E22=""),"必須欄不足",IF(COUNTIFS($A$16:$A$25,A22)<>1,"ID重複",IF(OR(NOT(ISNUMBER(D22)),NOT(ISNUMBER(F22)),NOT(ISNUMBER(G22))),"数値を入力",IF(OR(D22<=0,F22<0,AND(G22<>0,G22<>0.08,G22<>0.1)),"数量・価格・税率確認","OK"))))))
H23: =IF(I23="OK",ROUND(D23*F23,0),"") | I23: =IF(OR(A23="案件共通",ISNUMBER(SEARCH("~*",A23)),ISNUMBER(SEARCH("~?",A23)),ISNUMBER(SEARCH("~~",A23))),"IDに予約語・特殊文字不可",IF(COUNTA(A23:G23)=0,"",IF(OR(A23="",B23="",E23=""),"必須欄不足",IF(COUNTIFS($A$16:$A$25,A23)<>1,"ID重複",IF(OR(NOT(ISNUMBER(D23)),NOT(ISNUMBER(F23)),NOT(ISNUMBER(G23))),"数値を入力",IF(OR(D23<=0,F23<0,AND(G23<>0,G23<>0.08,G23<>0.1)),"数量・価格・税率確認","OK"))))))
H24: =IF(I24="OK",ROUND(D24*F24,0),"") | I24: =IF(OR(A24="案件共通",ISNUMBER(SEARCH("~*",A24)),ISNUMBER(SEARCH("~?",A24)),ISNUMBER(SEARCH("~~",A24))),"IDに予約語・特殊文字不可",IF(COUNTA(A24:G24)=0,"",IF(OR(A24="",B24="",E24=""),"必須欄不足",IF(COUNTIFS($A$16:$A$25,A24)<>1,"ID重複",IF(OR(NOT(ISNUMBER(D24)),NOT(ISNUMBER(F24)),NOT(ISNUMBER(G24))),"数値を入力",IF(OR(D24<=0,F24<0,AND(G24<>0,G24<>0.08,G24<>0.1)),"数量・価格・税率確認","OK"))))))
H25: =IF(I25="OK",ROUND(D25*F25,0),"") | I25: =IF(OR(A25="案件共通",ISNUMBER(SEARCH("~*",A25)),ISNUMBER(SEARCH("~?",A25)),ISNUMBER(SEARCH("~~",A25))),"IDに予約語・特殊文字不可",IF(COUNTA(A25:G25)=0,"",IF(OR(A25="",B25="",E25=""),"必須欄不足",IF(COUNTIFS($A$16:$A$25,A25)<>1,"ID重複",IF(OR(NOT(ISNUMBER(D25)),NOT(ISNUMBER(F25)),NOT(ISNUMBER(G25))),"数値を入力",IF(OR(D25<=0,F25<0,AND(G25<>0,G25<>0.08,G25<>0.1)),"数量・価格・税率確認","OK"))))))
G28: 入力状態 | I28: =IF(COUNTIFS(I16:I25,"OK")=0,"見積明細なし",IF(SUMPRODUCT((I16:I25<>"")*(I16:I25<>"OK"))>0,"見積明細を確認",IF(OR(NOT(ISNUMBER(B8)),B8<0,B8>1),"確定値引率を確認","OK"))) -> OK
G29: 税抜小計 | H29: =IF(I28="OK",SUM(H16:H25),"") -> 160000
A31: 明細IDは半角英数字で固定。原価も同じIDに紐付けます。数量変更で一式費用は増減しません。
A33: 税率は取引に応じて0・8%・10%を選択。値引き後明細金額を円単位四捨五入、税額は税率別に切り捨て。

Sheet 原価(木工所)
A2: 原価(木工所)
A4: 選択中の業種 | B4: =採算シミュレーション!B5 -> 木工所 | D4: =IF(B4="木工所","この原価を採算計算に使用中","この原価は現在の採算計算に使われていません") -> この原価を採算計算に使用中 | L4: COST-V1
L5: 原価入力状態 | M5: =IF(COUNTIFS(H16:H55,"OK")=0,"原価明細なし",IF(SUMPRODUCT((H16:H55<>"")*(H16:H55<>"OK"))>0,"原価明細を確認",IF(AND(B11<>"計上済み",B11<>"単価に含む",B11<>"今回は未算入"),"共通経費の扱い確認","OK"))) -> OK
A6: 材料・加工・外注・配送を、明細IDまたは「案件共通」に紐付けます。 | L6: 案件共通費 | M6: =SUMIFS(F16:F55,A16:A55,"案件共通") -> 8000
L7: 共通経費表示 | M7: =B11 -> 今回は未算入
A8: 数量連動：使用量/販売単位 × 原価単価 × 見積数量。一式：使用量 × 原価単価。
A11: 共通経費の扱い | B11: 今回は未算入
A13: 青色が入力欄。未算入の共通経費は利益に含まれません。既に単価に含む費用は二重計上しないでください。
A15: 対象明細ID | B15: 区分 | C15: 内容 | D15: 使用量・時間 | E15: 原価単価 | F15: 原価金額 | G15: 根拠・単位 | H15: 入力確認 | I15: 数量の扱い | J15: 見積数量 | K15: 適用単価 | L15: 明細ID | M15: 紐付く原価 | N15: 原価行数
A16: M001 | B16: 材料 | C16: テーブル材料 | D16: 1 | E16: 15000 | F16: =IF(H16="OK",ROUND(D16*K16*J16,0),"") -> 30000 | G16: 台当たり | H16: =IF(COUNTA(A16:E16)+COUNTA(G16)+COUNTA(I16)=0,"",IF(OR(A16="",B16="",C16="",I16=""),"必須欄不足",IF(AND(A16<>"案件共通",COUNTIFS(見積入力!$A$16:$A$25,A16)<>1),"ID未登録・重複",IF(OR(AND(I16<>"数量連動",I16<>"一式"),AND(A16="案件共通",I16<>"一式")),"数量の扱い確認",IF(OR(NOT(ISNUMBER(D16)),NOT(ISNUMBER(K16)),AND(B16<>"生産原価",E16=""),D16="",NOT(ISNUMBER(J16))),"数値を入力",IF(OR(D16<0,K16<0,J16<=0),"負数・数量確認","OK")))))) -> OK | I16: 数量連動 | J16: =IF(A16="","",IF(I16="一式",1,IFERROR(INDEX(見積入力!$D$16:$D$25,MATCH(A16,見積入力!$A$16:$A$25,0)),"ID未登録"))) -> 2 | K16: =IF(A16="","",E16) -> 15000 | L16: =IF(見積入力!A16="","",見積入力!A16) -> M001 | M16: =IF(L16="","",SUMIFS($F$16:$F$55,$A$16:$A$55,L16)) -> 50000 | N16: =IF(L16="","",COUNTIFS($A$16:$A$55,L16)) -> 2
A17: M001 | B17: 作業 | C17: テーブル作業 | D17: 10 | E17: 1000 | F17: =IF(H17="OK",ROUND(D17*K17*J17,0),"") -> 20000 | G17: 時間/台 | H17: =IF(COUNTA(A17:E17)+COUNTA(G17)+COUNTA(I17)=0,"",IF(OR(A17="",B17="",C17="",I17=""),"必須欄不足",IF(AND(A17<>"案件共通",COUNTIFS(見積入力!$A$16:$A$25,A17)<>1),"ID未登録・重複",IF(OR(AND(I17<>"数量連動",I17<>"一式"),AND(A17="案件共通",I17<>"一式")),"数量の扱い確認",IF(OR(NOT(ISNUMBER(D17)),NOT(ISNUMBER(K17)),AND(B17<>"生産原価",E17=""),D17="",NOT(ISNUMBER(J17))),"数値を入力",IF(OR(D17<0,K17<0,J17<=0),"負数・数量確認","OK")))))) -> OK | I17: 数量連動 | J17: =IF(A17="","",IF(I17="一式",1,IFERROR(INDEX(見積入力!$D$16:$D$25,MATCH(A17,見積入力!$A$16:$A$25,0)),"ID未登録"))) -> 2 | K17: =IF(A17="","",E17) -> 1000 | L17: =IF(見積入力!A17="","",見積入力!A17) -> M002 | M17: =IF(L17="","",SUMIFS($F$16:$F$55,$A$16:$A$55,L17)) -> 30000 | N17: =IF(L17="","",COUNTIFS($A$16:$A$55,L17)) -> 2
A18: M002 | B18: 材料 | C18: 椅子材料 | D18: 1 | E18: 5000 | F18: =IF(H18="OK",ROUND(D18*K18*J18,0),"") -> 20000 | G18: 脚当たり | H18: =IF(COUNTA(A18:E18)+COUNTA(G18)+COUNTA(I18)=0,"",IF(OR(A18="",B18="",C18="",I18=""),"必須欄不足",IF(AND(A18<>"案件共通",COUNTIFS(見積入力!$A$16:$A$25,A18)<>1),"ID未登録・重複",IF(OR(AND(I18<>"数量連動",I18<>"一式"),AND(A18="案件共通",I18<>"一式")),"数量の扱い確認",IF(OR(NOT(ISNUMBER(D18)),NOT(ISNUMBER(K18)),AND(B18<>"生産原価",E18=""),D18="",NOT(ISNUMBER(J18))),"数値を入力",IF(OR(D18<0,K18<0,J18<=0),"負数・数量確認","OK")))))) -> OK | I18: 数量連動 | J18: =IF(A18="","",IF(I18="一式",1,IFERROR(INDEX(見積入力!$D$16:$D$25,MATCH(A18,見積入力!$A$16:$A$25,0)),"ID未登録"))) -> 4 | K18: =IF(A18="","",E18) -> 5000 | L18: =IF(見積入力!A18="","",見積入力!A18) | M18: =IF(L18="","",SUMIFS($F$16:$F$55,$A$16:$A$55,L18)) | N18: =IF(L18="","",COUNTIFS($A$16:$A$55,L18))
A19: M002 | B19: 作業 | C19: 椅子作業 | D19: 2.5 | E19: 1000 | F19: =IF(H19="OK",ROUND(D19*K19*J19,0),"") -> 10000 | G19: 時間/脚 | H19: =IF(COUNTA(A19:E19)+COUNTA(G19)+COUNTA(I19)=0,"",IF(OR(A19="",B19="",C19="",I19=""),"必須欄不足",IF(AND(A19<>"案件共通",COUNTIFS(見積入力!$A$16:$A$25,A19)<>1),"ID未登録・重複",IF(OR(AND(I19<>"数量連動",I19<>"一式"),AND(A19="案件共通",I19<>"一式")),"数量の扱い確認",IF(OR(NOT(ISNUMBER(D19)),NOT(ISNUMBER(K19)),AND(B19<>"生産原価",E19=""),D19="",NOT(ISNUMBER(J19))),"数値を入力",IF(OR(D19<0,K19<0,J19<=0),"負数・数量確認","OK")))))) -> OK | I19: 数量連動 | J19: =IF(A19="","",IF(I19="一式",1,IFERROR(INDEX(見積入力!$D$16:$D$25,MATCH(A19,見積入力!$A$16:$A$25,0)),"ID未登録"))) -> 4 | K19: =IF(A19="","",E19) -> 1000 | L19: =IF(見積入力!A19="","",見積入力!A19) | M19: =IF(L19="","",SUMIFS($F$16:$F$55,$A$16:$A$55,L19)) | N19: =IF(L19="","",COUNTIFS($A$16:$A$55,L19))
A20: 案件共通 | B20: 配送 | C20: 一括配送 | D20: 1 | E20: 8000 | F20: =IF(H20="OK",ROUND(D20*K20*J20,0),"") -> 8000 | G20: 納品1回 | H20: =IF(COUNTA(A20:E20)+COUNTA(G20)+COUNTA(I20)=0,"",IF(OR(A20="",B20="",C20="",I20=""),"必須欄不足",IF(AND(A20<>"案件共通",COUNTIFS(見積入力!$A$16:$A$25,A20)<>1),"ID未登録・重複",IF(OR(AND(I20<>"数量連動",I20<>"一式"),AND(A20="案件共通",I20<>"一式")),"数量の扱い確認",IF(OR(NOT(ISNUMBER(D20)),NOT(ISNUMBER(K20)),AND(B20<>"生産原価",E20=""),D20="",NOT(ISNUMBER(J20))),"数値を入力",IF(OR(D20<0,K20<0,J20<=0),"負数・数量確認","OK")))))) -> OK | I20: 一式 | J20: =IF(A20="","",IF(I20="一式",1,IFERROR(INDEX(見積入力!$D$16:$D$25,MATCH(A20,見積入力!$A$16:$A$25,0)),"ID未登録"))) -> 1 | K20: =IF(A20="","",E20) -> 8000 | L20: =IF(見積入力!A20="","",見積入力!A20) | M20: =IF(L20="","",SUMIFS($F$16:$F$55,$A$16:$A$55,L20)) | N20: =IF(L20="","",COUNTIFS($A$16:$A$55,L20))
F21: =IF(H21="OK",ROUND(D21*K21*J21,0),"") | H21: =IF(COUNTA(A21:E21)+COUNTA(G21)+COUNTA(I21)=0,"",IF(OR(A21="",B21="",C21="",I21=""),"必須欄不足",IF(AND(A21<>"案件共通",COUNTIFS(見積入力!$A$16:$A$25,A21)<>1),"ID未登録・重複",IF(OR(AND(I21<>"数量連動",I21<>"一式"),AND(A21="案件共通",I21<>"一式")),"数量の扱い確認",IF(OR(NOT(ISNUMBER(D21)),NOT(ISNUMBER(K21)),AND(B21<>"生産原価",E21=""),D21="",NOT(ISNUMBER(J21))),"数値を入力",IF(OR(D21<0,K21<0,J21<=0),"負数・数量確認","OK")))))) | J21: =IF(A21="","",IF(I21="一式",1,IFERROR(INDEX(見積入力!$D$16:$D$25,MATCH(A21,見積入力!$A$16:$A$25,0)),"ID未登録"))) | K21: =IF(A21="","",E21) | L21: =IF(見積入力!A21="","",見積入力!A21) | M21: =IF(L21="","",SUMIFS($F$16:$F$55,$A$16:$A$55,L21)) | N21: =IF(L21="","",COUNTIFS($A$16:$A$55,L21))
F22: =IF(H22="OK",ROUND(D22*K22*J22,0),"") | H22: =IF(COUNTA(A22:E22)+COUNTA(G22)+COUNTA(I22)=0,"",IF(OR(A22="",B22="",C22="",I22=""),"必須欄不足",IF(AND(A22<>"案件共通",COUNTIFS(見積入力!$A$16:$A$25,A22)<>1),"ID未登録・重複",IF(OR(AND(I22<>"数量連動",I22<>"一式"),AND(A22="案件共通",I22<>"一式")),"数量の扱い確認",IF(OR(NOT(ISNUMBER(D22)),NOT(ISNUMBER(K22)),AND(B22<>"生産原価",E22=""),D22="",NOT(ISNUMBER(J22))),"数値を入力",IF(OR(D22<0,K22<0,J22<=0),"負数・数量確認","OK")))))) | J22: =IF(A22="","",IF(I22="一式",1,IFERROR(INDEX(見積入力!$D$16:$D$25,MATCH(A22,見積入力!$A$16:$A$25,0)),"ID未登録"))) | K22: =IF(A22="","",E22) | L22: =IF(見積入力!A22="","",見積入力!A22) | M22: =IF(L22="","",SUMIFS($F$16:$F$55,$A$16:$A$55,L22)) | N22: =IF(L22="","",COUNTIFS($A$16:$A$55,L22))
F23: =IF(H23="OK",ROUND(D23*K23*J23,0),"") | H23: =IF(COUNTA(A23:E23)+COUNTA(G23)+COUNTA(I23)=0,"",IF(OR(A23="",B23="",C23="",I23=""),"必須欄不足",IF(AND(A23<>"案件共通",COUNTIFS(見積入力!$A$16:$A$25,A23)<>1),"ID未登録・重複",IF(OR(AND(I23<>"数量連動",I23<>"一式"),AND(A23="案件共通",I23<>"一式")),"数量の扱い確認",IF(OR(NOT(ISNUMBER(D23)),NOT(ISNUMBER(K23)),AND(B23<>"生産原価",E23=""),D23="",NOT(ISNUMBER(J23))),"数値を入力",IF(OR(D23<0,K23<0,J23<=0),"負数・数量確認","OK")))))) | J23: =IF(A23="","",IF(I23="一式",1,IFERROR(INDEX(見積入力!$D$16:$D$25,MATCH(A23,見積入力!$A$16:$A$25,0)),"ID未登録"))) | K23: =IF(A23="","",E23) | L23: =IF(見積入力!A23="","",見積入力!A23) | M23: =IF(L23="","",SUMIFS($F$16:$F$55,$A$16:$A$55,L23)) | N23: =IF(L23="","",COUNTIFS($A$16:$A$55,L23))
F24: =IF(H24="OK",ROUND(D24*K24*J24,0),"") | H24: =IF(COUNTA(A24:E24)+COUNTA(G24)+COUNTA(I24)=0,"",IF(OR(A24="",B24="",C24="",I24=""),"必須欄不足",IF(AND(A24<>"案件共通",COUNTIFS(見積入力!$A$16:$A$25,A24)<>1),"ID未登録・重複",IF(OR(AND(I24<>"数量連動",I24<>"一式"),AND(A24="案件共通",I24<>"一式")),"数量の扱い確認",IF(OR(NOT(ISNUMBER(D24)),NOT(ISNUMBER(K24)),AND(B24<>"生産原価",E24=""),D24="",NOT(ISNUMBER(J24))),"数値を入力",IF(OR(D24<0,K24<0,J24<=0),"負数・数量確認","OK")))))) | J24: =IF(A24="","",IF(I24="一式",1,IFERROR(INDEX(見積入力!$D$16:$D$25,MATCH(A24,見積入力!$A$16:$A$25,0)),"ID未登録"))) | K24: =IF(A24="","",E24) | L24: =IF(見積入力!A24="","",見積入力!A24) | M24: =IF(L24="","",SUMIFS($F$16:$F$55,$A$16:$A$55,L24)) | N24: =IF(L24="","",COUNTIFS($A$16:$A$55,L24))
F25: =IF(H25="OK",ROUND(D25*K25*J25,0),"") | H25: =IF(COUNTA(A25:E25)+COUNTA(G25)+COUNTA(I25)=0,"",IF(OR(A25="",B25="",C25="",I25=""),"必須欄不足",IF(AND(A25<>"案件共通",COUNTIFS(見積入力!$A$16:$A$25,A25)<>1),"ID未登録・重複",IF(OR(AND(I25<>"数量連動",I25<>"一式"),AND(A25="案件共通",I25<>"一式")),"数量の扱い確認",IF(OR(NOT(ISNUMBER(D25)),NOT(ISNUMBER(K25)),AND(B25<>"生産原価",E25=""),D25="",NOT(ISNUMBER(J25))),"数値を入力",IF(OR(D25<0,K25<0,J25<=0),"負数・数量確認","OK")))))) | J25: =IF(A25="","",IF(I25="一式",1,IFERROR(INDEX(見積入力!$D$16:$D$25,MATCH(A25,見積入力!$A$16:$A$25,0)),"ID未登録"))) | K25: =IF(A25="","",E25) | L25: =IF(見積入力!A25="","",見積入力!A25) | M25: =IF(L25="","",SUMIFS($F$16:$F$55,$A$16:$A$55,L25)) | N25: =IF(L25="","",COUNTIFS($A$16:$A$55,L25))
F26: =IF(H26="OK",ROUND(D26*K26*J26,0),"") | H26: =IF(COUNTA(A26:E26)+COUNTA(G26)+COUNTA(I26)=0,"",IF(OR(A26="",B26="",C26="",I26=""),"必須欄不足",IF(AND(A26<>"案件共通",COUNTIFS(見積入力!$A$16:$A$25,A26)<>1),"ID未登録・重複",IF(OR(AND(I26<>"数量連動",I26<>"一式"),AND(A26="案件共通",I26<>"一式")),"数量の扱い確認",IF(OR(NOT(ISNUMBER(D26)),NOT(ISNUMBER(K26)),AND(B26<>"生産原価",E26=""),D26="",NOT(ISNUMBER(J26))),"数値を入力",IF(OR(D26<0,K26<0,J26<=0),"負数・数量確認","OK")))))) | J26: =IF(A26="","",IF(I26="一式",1,IFERROR(INDEX(見積入力!$D$16:$D$25,MATCH(A26,見積入力!$A$16:$A$25,0)),"ID未登録"))) | K26: =IF(A26="","",E26)
F27: =IF(H27="OK",ROUND(D27*K27*J27,0),"") | H27: =IF(COUNTA(A27:E27)+COUNTA(G27)+COUNTA(I27)=0,"",IF(OR(A27="",B27="",C27="",I27=""),"必須欄不足",IF(AND(A27<>"案件共通",COUNTIFS(見積入力!$A$16:$A$25,A27)<>1),"ID未登録・重複",IF(OR(AND(I27<>"数量連動",I27<>"一式"),AND(A27="案件共通",I27<>"一式")),"数量の扱い確認",IF(OR(NOT(ISNUMBER(D27)),NOT(ISNUMBER(K27)),AND(B27<>"生産原価",E27=""),D27="",NOT(ISNUMBER(J27))),"数値を入力",IF(OR(D27<0,K27<0,J27<=0),"負数・数量確認","OK")))))) | J27: =IF(A27="","",IF(I27="一式",1,IFERROR(INDEX(見積入力!$D$16:$D$25,MATCH(A27,見積入力!$A$16:$A$25,0)),"ID未登録"))) | K27: =IF(A27="","",E27)
F28: =IF(H28="OK",ROUND(D28*K28*J28,0),"") | H28: =IF(COUNTA(A28:E28)+COUNTA(G28)+COUNTA(I28)=0,"",IF(OR(A28="",B28="",C28="",I28=""),"必須欄不足",IF(AND(A28<>"案件共通",COUNTIFS(見積入力!$A$16:$A$25,A28)<>1),"ID未登録・重複",IF(OR(AND(I28<>"数量連動",I28<>"一式"),AND(A28="案件共通",I28<>"一式")),"数量の扱い確認",IF(OR(NOT(ISNUMBER(D28)),NOT(ISNUMBER(K28)),AND(B28<>"生産原価",E28=""),D28="",NOT(ISNUMBER(J28))),"数値を入力",IF(OR(D28<0,K28<0,J28<=0),"負数・数量確認","OK")))))) | J28: =IF(A28="","",IF(I28="一式",1,IFERROR(INDEX(見積入力!$D$16:$D$25,MATCH(A28,見積入力!$A$16:$A$25,0)),"ID未登録"))) | K28: =IF(A28="","",E28)
F29: =IF(H29="OK",ROUND(D29*K29*J29,0),"") | H29: =IF(COUNTA(A29:E29)+COUNTA(G29)+COUNTA(I29)=0,"",IF(OR(A29="",B29="",C29="",I29=""),"必須欄不足",IF(AND(A29<>"案件共通",COUNTIFS(見積入力!$A$16:$A$25,A29)<>1),"ID未登録・重複",IF(OR(AND(I29<>"数量連動",I29<>"一式"),AND(A29="案件共通",I29<>"一式")),"数量の扱い確認",IF(OR(NOT(ISNUMBER(D29)),NOT(ISNUMBER(K29)),AND(B29<>"生産原価",E29=""),D29="",NOT(ISNUMBER(J29))),"数値を入力",IF(OR(D29<0,K29<0,J29<=0),"負数・数量確認","OK")))))) | J29: =IF(A29="","",IF(I29="一式",1,IFERROR(INDEX(見積入力!$D$16:$D$25,MATCH(A29,見積入力!$A$16:$A$25,0)),"ID未登録"))) | K29: =IF(A29="","",E29)
F30: =IF(H30="OK",ROUND(D30*K30*J30,0),"") | H30: =IF(COUNTA(A30:E30)+COUNTA(G30)+COUNTA(I30)=0,"",IF(OR(A30="",B30="",C30="",I30=""),"必須欄不足",IF(AND(A30<>"案件共通",COUNTIFS(見積入力!$A$16:$A$25,A30)<>1),"ID未登録・重複",IF(OR(AND(I30<>"数量連動",I30<>"一式"),AND(A30="案件共通",I30<>"一式")),"数量の扱い確認",IF(OR(NOT(ISNUMBER(D30)),NOT(ISNUMBER(K30)),AND(B30<>"生産原価",E30=""),D30="",NOT(ISNUMBER(J30))),"数値を入力",IF(OR(D30<0,K30<0,J30<=0),"負数・数量確認","OK")))))) | J30: =IF(A30="","",IF(I30="一式",1,IFERROR(INDEX(見積入力!$D$16:$D$25,MATCH(A30,見積入力!$A$16:$A$25,0)),"ID未登録"))) | K30: =IF(A30="","",E30)
F31: =IF(H31="OK",ROUND(D31*K31*J31,0),"") | H31: =IF(COUNTA(A31:E31)+COUNTA(G31)+COUNTA(I31)=0,"",IF(OR(A31="",B31="",C31="",I31=""),"必須欄不足",IF(AND(A31<>"案件共通",COUNTIFS(見積入力!$A$16:$A$25,A31)<>1),"ID未登録・重複",IF(OR(AND(I31<>"数量連動",I31<>"一式"),AND(A31="案件共通",I31<>"一式")),"数量の扱い確認",IF(OR(NOT(ISNUMBER(D31)),NOT(ISNUMBER(K31)),AND(B31<>"生産原価",E31=""),D31="",NOT(ISNUMBER(J31))),"数値を入力",IF(OR(D31<0,K31<0,J31<=0),"負数・数量確認","OK")))))) | J31: =IF(A31="","",IF(I31="一式",1,IFERROR(INDEX(見積入力!$D$16:$D$25,MATCH(A31,見積入力!$A$16:$A$25,0)),"ID未登録"))) | K31: =IF(A31="","",E31)
F32: =IF(H32="OK",ROUND(D32*K32*J32,0),"") | H32: =IF(COUNTA(A32:E32)+COUNTA(G32)+COUNTA(I32)=0,"",IF(OR(A32="",B32="",C32="",I32=""),"必須欄不足",IF(AND(A32<>"案件共通",COUNTIFS(見積入力!$A$16:$A$25,A32)<>1),"ID未登録・重複",IF(OR(AND(I32<>"数量連動",I32<>"一式"),AND(A32="案件共通",I32<>"一式")),"数量の扱い確認",IF(OR(NOT(ISNUMBER(D32)),NOT(ISNUMBER(K32)),AND(B32<>"生産原価",E32=""),D32="",NOT(ISNUMBER(J32))),"数値を入力",IF(OR(D32<0,K32<0,J32<=0),"負数・数量確認","OK")))))) | J32: =IF(A32="","",IF(I32="一式",1,IFERROR(INDEX(見積入力!$D$16:$D$25,MATCH(A32,見積入力!$A$16:$A$25,0)),"ID未登録"))) | K32: =IF(A32="","",E32)
F33: =IF(H33="OK",ROUND(D33*K33*J33,0),"") | H33: =IF(COUNTA(A33:E33)+COUNTA(G33)+COUNTA(I33)=0,"",IF(OR(A33="",B33="",C33="",I33=""),"必須欄不足",IF(AND(A33<>"案件共通",COUNTIFS(見積入力!$A$16:$A$25,A33)<>1),"ID未登録・重複",IF(OR(AND(I33<>"数量連動",I33<>"一式"),AND(A33="案件共通",I33<>"一式")),"数量の扱い確認",IF(OR(NOT(ISNUMBER(D33)),NOT(ISNUMBER(K33)),AND(B33<>"生産原価",E33=""),D33="",NOT(ISNUMBER(J33))),"数値を入力",IF(OR(D33<0,K33<0,J33<=0),"負数・数量確認","OK")))))) | J33: =IF(A33="","",IF(I33="一式",1,IFERROR(INDEX(見積入力!$D$16:$D$25,MATCH(A33,見積入力!$A$16:$A$25,0)),"ID未登録"))) | K33: =IF(A33="","",E33)
F34: =IF(H34="OK",ROUND(D34*K34*J34,0),"") | H34: =IF(COUNTA(A34:E34)+COUNTA(G34)+COUNTA(I34)=0,"",IF(OR(A34="",B34="",C34="",I34=""),"必須欄不足",IF(AND(A34<>"案件共通",COUNTIFS(見積入力!$A$16:$A$25,A34)<>1),"ID未登録・重複",IF(OR(AND(I34<>"数量連動",I34<>"一式"),AND(A34="案件共通",I34<>"一式")),"数量の扱い確認",IF(OR(NOT(ISNUMBER(D34)),NOT(ISNUMBER(K34)),AND(B34<>"生産原価",E34=""),D34="",NOT(ISNUMBER(J34))),"数値を入力",IF(OR(D34<0,K34<0,J34<=0),"負数・数量確認","OK")))))) | J34: =IF(A34="","",IF(I34="一式",1,IFERROR(INDEX(見積入力!$D$16:$D$25,MATCH(A34,見積入力!$A$16:$A$25,0)),"ID未登録"))) | K34: =IF(A34="","",E34)
F35: =IF(H35="OK",ROUND(D35*K35*J35,0),"") | H35: =IF(COUNTA(A35:E35)+COUNTA(G35)+COUNTA(I35)=0,"",IF(OR(A35="",B35="",C35="",I35=""),"必須欄不足",IF(AND(A35<>"案件共通",COUNTIFS(見積入力!$A$16:$A$25,A35)<>1),"ID未登録・重複",IF(OR(AND(I35<>"数量連動",I35<>"一式"),AND(A35="案件共通",I35<>"一式")),"数量の扱い確認",IF(OR(NOT(ISNUMBER(D35)),NOT(ISNUMBER(K35)),AND(B35<>"生産原価",E35=""),D35="",NOT(ISNUMBER(J35))),"数値を入力",IF(OR(D35<0,K35<0,J35<=0),"負数・数量確認","OK")))))) | J35: =IF(A35="","",IF(I35="一式",1,IFERROR(INDEX(見積入力!$D$16:$D$25,MATCH(A35,見積入力!$A$16:$A$25,0)),"ID未登録"))) | K35: =IF(A35="","",E35)
F36: =IF(H36="OK",ROUND(D36*K36*J36,0),"") | H36: =IF(COUNTA(A36:E36)+COUNTA(G36)+COUNTA(I36)=0,"",IF(OR(A36="",B36="",C36="",I36=""),"必須欄不足",IF(AND(A36<>"案件共通",COUNTIFS(見積入力!$A$16:$A$25,A36)<>1),"ID未登録・重複",IF(OR(AND(I36<>"数量連動",I36<>"一式"),AND(A36="案件共通",I36<>"一式")),"数量の扱い確認",IF(OR(NOT(ISNUMBER(D36)),NOT(ISNUMBER(K36)),AND(B36<>"生産原価",E36=""),D36="",NOT(ISNUMBER(J36))),"数値を入力",IF(OR(D36<0,K36<0,J36<=0),"負数・数量確認","OK")))))) | J36: =IF(A36="","",IF(I36="一式",1,IFERROR(INDEX(見積入力!$D$16:$D$25,MATCH(A36,見積入力!$A$16:$A$25,0)),"ID未登録"))) | K36: =IF(A36="","",E36)
F37: =IF(H37="OK",ROUND(D37*K37*J37,0),"") | H37: =IF(COUNTA(A37:E37)+COUNTA(G37)+COUNTA(I37)=0,"",IF(OR(A37="",B37="",C37="",I37=""),"必須欄不足",IF(AND(A37<>"案件共通",COUNTIFS(見積入力!$A$16:$A$25,A37)<>1),"ID未登録・重複",IF(OR(AND(I37<>"数量連動",I37<>"一式"),AND(A37="案件共通",I37<>"一式")),"数量の扱い確認",IF(OR(NOT(ISNUMBER(D37)),NOT(ISNUMBER(K37)),AND(B37<>"生産原価",E37=""),D37="",NOT(ISNUMBER(J37))),"数値を入力",IF(OR(D37<0,K37<0,J37<=0),"負数・数量確認","OK")))))) | J37: =IF(A37="","",IF(I37="一式",1,IFERROR(INDEX(見積入力!$D$16:$D$25,MATCH(A37,見積入力!$A$16:$A$25,0)),"ID未登録"))) | K37: =IF(A37="","",E37)
... F55: =IF(H55="OK",ROUND(D55*K55*J55,0),"") | H55: =IF(COUNTA(A55:E55)+COUNTA(G55)+COUNTA(I55)=0,"",IF(OR(A55="",B55="",C55="",I55=""),"必須欄不足",IF(AND(A55<>"案件共通",COUNTIFS(見積入力!$A$16:$A$25,A55)<>1),"ID未登録・重複",IF(OR(AND(I55<>"数量連動",I55<>"一式"),AND(A55="案件共通",I55<>"一式")),"数量の扱い確認",IF(OR(NOT(ISNUMBER(D55)),NOT(ISNUMBER(K55)),AND(B55<>"生産原価",E55=""),D55="",NOT(ISNUMBER(J55))),"数値を入力",IF(OR(D55<0,K55<0,J55<=0),"負数・数量確認","OK")))))) | J55: =IF(A55="","",IF(I55="一式",1,IFERROR(INDEX(見積入力!$D$16:$D$25,MATCH(A55,見積入力!$A$16:$A$25,0)),"ID未登録"))) | K55: =IF(A55="","",E55)

Sheet 原価(農家)
A2: 原価(農家)
A4: 選択中の業種 | B4: =採算シミュレーション!B5 -> 木工所 | D4: =IF(B4="農家","この原価を採算計算に使用中","この原価は現在の採算計算に使われていません") -> この原価は現在の採算計算に使われていません | L4: COST-V1
A5: 作物・栽培期間 | B5: サンプル野菜・1作期 | E5: 種苗・肥料・資材 | F5: 300000 | L5: 原価入力状態 | M5: =IF(COUNTIFS(H16:H55,"OK")=0,"原価明細なし",IF(SUMPRODUCT((H16:H55<>"")*(H16:H55<>"OK"))>0,"原価明細を確認",IF(AND(B11<>"計上済み",B11<>"単価に含む",B11<>"今回は未算入"),"共通経費の扱い確認",IF(OR(COUNT(F5:F8)<>4,MIN(F5:F8)<0,NOT(ISNUMBER(B7)),B7<=0,B8=""),"生産費用・収穫量確認","OK")))) -> OK
A6: 生産費用合計 | B6: =SUM(F5:F8) -> 1000000 | E6: 栽培・収穫作業 | F6: 400000 | L6: 案件共通費 | M6: =SUMIFS(F16:F55,A16:A55,"案件共通") -> 10000
A7: 販売可能収穫量 | B7: 5000 | E7: その他の直接費 | F7: 100000 | L7: 共通経費表示 | M7: =B11 -> 計上済み
A8: 生産量の単位 | B8: kg | E8: 共通経費の割当 | F8: 200000
A9: 生産原価単価 | B9: =IF(AND(COUNT(F5:F8)=4,MIN(F5:F8)>=0,ISNUMBER(B7),B7>0),B6/B7,"") -> 200
A11: 共通経費の扱い | B11: 計上済み
A13: 青色が入力欄。未算入の共通経費は利益に含まれません。既に単価に含む費用は二重計上しないでください。
A15: 対象明細ID | B15: 区分 | C15: 内容 | D15: 使用量・時間 | E15: 原価単価 | F15: 原価金額 | G15: 根拠・単位 | H15: 入力確認 | I15: 数量の扱い | J15: 見積数量 | K15: 適用単価 | L15: 明細ID | M15: 紐付く原価 | N15: 原価行数
A16: M001 | B16: 生産原価 | C16: 対象出荷分の生産原価 | D16: 5 | F16: =IF(H16="OK",ROUND(D16*K16*J16,0),"") -> 2000 | G16: kg/箱・単価自動 | H16: =IF(COUNTA(A16:E16)+COUNTA(G16)+COUNTA(I16)=0,"",IF(OR(A16="",B16="",C16="",I16=""),"必須欄不足",IF(AND(A16<>"案件共通",COUNTIFS(見積入力!$A$16:$A$25,A16)<>1),"ID未登録・重複",IF(OR(AND(I16<>"数量連動",I16<>"一式"),AND(A16="案件共通",I16<>"一式")),"数量の扱い確認",IF(OR(NOT(ISNUMBER(D16)),NOT(ISNUMBER(K16)),AND(B16<>"生産原価",E16=""),D16="",NOT(ISNUMBER(J16))),"数値を入力",IF(OR(D16<0,K16<0,J16<=0),"負数・数量確認","OK")))))) -> OK | I16: 数量連動 | J16: =IF(A16="","",IF(I16="一式",1,IFERROR(INDEX(見積入力!$D$16:$D$25,MATCH(A16,見積入力!$A$16:$A$25,0)),"ID未登録"))) -> 2 | K16: =IF(A16="","",IF(B16="生産原価",$B$9,E16)) -> 200 | L16: =IF(見積入力!A16="","",見積入力!A16) -> M001 | M16: =IF(L16="","",SUMIFS($F$16:$F$55,$A$16:$A$55,L16)) -> 2600 | N16: =IF(L16="","",COUNTIFS($A$16:$A$55,L16)) -> 3
A17: M001 | B17: 材料 | C17: 箱・包装材 | D17: 1 | E17: 150 | F17: =IF(H17="OK",ROUND(D17*K17*J17,0),"") -> 300 | G17: 箱当たり | H17: =IF(COUNTA(A17:E17)+COUNTA(G17)+COUNTA(I17)=0,"",IF(OR(A17="",B17="",C17="",I17=""),"必須欄不足",IF(AND(A17<>"案件共通",COUNTIFS(見積入力!$A$16:$A$25,A17)<>1),"ID未登録・重複",IF(OR(AND(I17<>"数量連動",I17<>"一式"),AND(A17="案件共通",I17<>"一式")),"数量の扱い確認",IF(OR(NOT(ISNUMBER(D17)),NOT(ISNUMBER(K17)),AND(B17<>"生産原価",E17=""),D17="",NOT(ISNUMBER(J17))),"数値を入力",IF(OR(D17<0,K17<0,J17<=0),"負数・数量確認","OK")))))) -> OK | I17: 数量連動 | J17: =IF(A17="","",IF(I17="一式",1,IFERROR(INDEX(見積入力!$D$16:$D$25,MATCH(A17,見積入力!$A$16:$A$25,0)),"ID未登録"))) -> 2 | K17: =IF(A17="","",IF(B17="生産原価",$B$9,E17)) -> 150 | L17: =IF(見積入力!A17="","",見積入力!A17) -> M002 | M17: =IF(L17="","",SUMIFS($F$16:$F$55,$A$16:$A$55,L17)) -> 0 | N17: =IF(L17="","",COUNTIFS($A$16:$A$55,L17)) -> 0
A18: M001 | B18: 作業 | C18: 選別・梱包 | D18: 0.1 | E18: 1500 | F18: =IF(H18="OK",ROUND(D18*K18*J18,0),"") -> 300 | G18: 時間/箱 | H18: =IF(COUNTA(A18:E18)+COUNTA(G18)+COUNTA(I18)=0,"",IF(OR(A18="",B18="",C18="",I18=""),"必須欄不足",IF(AND(A18<>"案件共通",COUNTIFS(見積入力!$A$16:$A$25,A18)<>1),"ID未登録・重複",IF(OR(AND(I18<>"数量連動",I18<>"一式"),AND(A18="案件共通",I18<>"一式")),"数量の扱い確認",IF(OR(NOT(ISNUMBER(D18)),NOT(ISNUMBER(K18)),AND(B18<>"生産原価",E18=""),D18="",NOT(ISNUMBER(J18))),"数値を入力",IF(OR(D18<0,K18<0,J18<=0),"負数・数量確認","OK")))))) -> OK | I18: 数量連動 | J18: =IF(A18="","",IF(I18="一式",1,IFERROR(INDEX(見積入力!$D$16:$D$25,MATCH(A18,見積入力!$A$16:$A$25,0)),"ID未登録"))) -> 2 | K18: =IF(A18="","",IF(B18="生産原価",$B$9,E18)) -> 1500 | L18: =IF(見積入力!A18="","",見積入力!A18) | M18: =IF(L18="","",SUMIFS($F$16:$F$55,$A$16:$A$55,L18)) | N18: =IF(L18="","",COUNTIFS($A$16:$A$55,L18))
A19: 案件共通 | B19: 配送 | C19: 今回の配送 | D19: 1 | E19: 10000 | F19: =IF(H19="OK",ROUND(D19*K19*J19,0),"") -> 10000 | G19: 出荷1回 | H19: =IF(COUNTA(A19:E19)+COUNTA(G19)+COUNTA(I19)=0,"",IF(OR(A19="",B19="",C19="",I19=""),"必須欄不足",IF(AND(A19<>"案件共通",COUNTIFS(見積入力!$A$16:$A$25,A19)<>1),"ID未登録・重複",IF(OR(AND(I19<>"数量連動",I19<>"一式"),AND(A19="案件共通",I19<>"一式")),"数量の扱い確認",IF(OR(NOT(ISNUMBER(D19)),NOT(ISNUMBER(K19)),AND(B19<>"生産原価",E19=""),D19="",NOT(ISNUMBER(J19))),"数値を入力",IF(OR(D19<0,K19<0,J19<=0),"負数・数量確認","OK")))))) -> OK | I19: 一式 | J19: =IF(A19="","",IF(I19="一式",1,IFERROR(INDEX(見積入力!$D$16:$D$25,MATCH(A19,見積入力!$A$16:$A$25,0)),"ID未登録"))) -> 1 | K19: =IF(A19="","",IF(B19="生産原価",$B$9,E19)) -> 10000 | L19: =IF(見積入力!A19="","",見積入力!A19) | M19: =IF(L19="","",SUMIFS($F$16:$F$55,$A$16:$A$55,L19)) | N19: =IF(L19="","",COUNTIFS($A$16:$A$55,L19))
F20: =IF(H20="OK",ROUND(D20*K20*J20,0),"") | H20: =IF(COUNTA(A20:E20)+COUNTA(G20)+COUNTA(I20)=0,"",IF(OR(A20="",B20="",C20="",I20=""),"必須欄不足",IF(AND(A20<>"案件共通",COUNTIFS(見積入力!$A$16:$A$25,A20)<>1),"ID未登録・重複",IF(OR(AND(I20<>"数量連動",I20<>"一式"),AND(A20="案件共通",I20<>"一式")),"数量の扱い確認",IF(OR(NOT(ISNUMBER(D20)),NOT(ISNUMBER(K20)),AND(B20<>"生産原価",E20=""),D20="",NOT(ISNUMBER(J20))),"数値を入力",IF(OR(D20<0,K20<0,J20<=0),"負数・数量確認","OK")))))) | J20: =IF(A20="","",IF(I20="一式",1,IFERROR(INDEX(見積入力!$D$16:$D$25,MATCH(A20,見積入力!$A$16:$A$25,0)),"ID未登録"))) | K20: =IF(A20="","",IF(B20="生産原価",$B$9,E20)) | L20: =IF(見積入力!A20="","",見積入力!A20) | M20: =IF(L20="","",SUMIFS($F$16:$F$55,$A$16:$A$55,L20)) | N20: =IF(L20="","",COUNTIFS($A$16:$A$55,L20))
F21: =IF(H21="OK",ROUND(D21*K21*J21,0),"") | H21: =IF(COUNTA(A21:E21)+COUNTA(G21)+COUNTA(I21)=0,"",IF(OR(A21="",B21="",C21="",I21=""),"必須欄不足",IF(AND(A21<>"案件共通",COUNTIFS(見積入力!$A$16:$A$25,A21)<>1),"ID未登録・重複",IF(OR(AND(I21<>"数量連動",I21<>"一式"),AND(A21="案件共通",I21<>"一式")),"数量の扱い確認",IF(OR(NOT(ISNUMBER(D21)),NOT(ISNUMBER(K21)),AND(B21<>"生産原価",E21=""),D21="",NOT(ISNUMBER(J21))),"数値を入力",IF(OR(D21<0,K21<0,J21<=0),"負数・数量確認","OK")))))) | J21: =IF(A21="","",IF(I21="一式",1,IFERROR(INDEX(見積入力!$D$16:$D$25,MATCH(A21,見積入力!$A$16:$A$25,0)),"ID未登録"))) | K21: =IF(A21="","",IF(B21="生産原価",$B$9,E21)) | L21: =IF(見積入力!A21="","",見積入力!A21) | M21: =IF(L21="","",SUMIFS($F$16:$F$55,$A$16:$A$55,L21)) | N21: =IF(L21="","",COUNTIFS($A$16:$A$55,L21))
F22: =IF(H22="OK",ROUND(D22*K22*J22,0),"") | H22: =IF(COUNTA(A22:E22)+COUNTA(G22)+COUNTA(I22)=0,"",IF(OR(A22="",B22="",C22="",I22=""),"必須欄不足",IF(AND(A22<>"案件共通",COUNTIFS(見積入力!$A$16:$A$25,A22)<>1),"ID未登録・重複",IF(OR(AND(I22<>"数量連動",I22<>"一式"),AND(A22="案件共通",I22<>"一式")),"数量の扱い確認",IF(OR(NOT(ISNUMBER(D22)),NOT(ISNUMBER(K22)),AND(B22<>"生産原価",E22=""),D22="",NOT(ISNUMBER(J22))),"数値を入力",IF(OR(D22<0,K22<0,J22<=0),"負数・数量確認","OK")))))) | J22: =IF(A22="","",IF(I22="一式",1,IFERROR(INDEX(見積入力!$D$16:$D$25,MATCH(A22,見積入力!$A$16:$A$25,0)),"ID未登録"))) | K22: =IF(A22="","",IF(B22="生産原価",$B$9,E22)) | L22: =IF(見積入力!A22="","",見積入力!A22) | M22: =IF(L22="","",SUMIFS($F$16:$F$55,$A$16:$A$55,L22)) | N22: =IF(L22="","",COUNTIFS($A$16:$A$55,L22))
F23: =IF(H23="OK",ROUND(D23*K23*J23,0),"") | H23: =IF(COUNTA(A23:E23)+COUNTA(G23)+COUNTA(I23)=0,"",IF(OR(A23="",B23="",C23="",I23=""),"必須欄不足",IF(AND(A23<>"案件共通",COUNTIFS(見積入力!$A$16:$A$25,A23)<>1),"ID未登録・重複",IF(OR(AND(I23<>"数量連動",I23<>"一式"),AND(A23="案件共通",I23<>"一式")),"数量の扱い確認",IF(OR(NOT(ISNUMBER(D23)),NOT(ISNUMBER(K23)),AND(B23<>"生産原価",E23=""),D23="",NOT(ISNUMBER(J23))),"数値を入力",IF(OR(D23<0,K23<0,J23<=0),"負数・数量確認","OK")))))) | J23: =IF(A23="","",IF(I23="一式",1,IFERROR(INDEX(見積入力!$D$16:$D$25,MATCH(A23,見積入力!$A$16:$A$25,0)),"ID未登録"))) | K23: =IF(A23="","",IF(B23="生産原価",$B$9,E23)) | L23: =IF(見積入力!A23="","",見積入力!A23) | M23: =IF(L23="","",SUMIFS($F$16:$F$55,$A$16:$A$55,L23)) | N23: =IF(L23="","",COUNTIFS($A$16:$A$55,L23))
F24: =IF(H24="OK",ROUND(D24*K24*J24,0),"") | H24: =IF(COUNTA(A24:E24)+COUNTA(G24)+COUNTA(I24)=0,"",IF(OR(A24="",B24="",C24="",I24=""),"必須欄不足",IF(AND(A24<>"案件共通",COUNTIFS(見積入力!$A$16:$A$25,A24)<>1),"ID未登録・重複",IF(OR(AND(I24<>"数量連動",I24<>"一式"),AND(A24="案件共通",I24<>"一式")),"数量の扱い確認",IF(OR(NOT(ISNUMBER(D24)),NOT(ISNUMBER(K24)),AND(B24<>"生産原価",E24=""),D24="",NOT(ISNUMBER(J24))),"数値を入力",IF(OR(D24<0,K24<0,J24<=0),"負数・数量確認","OK")))))) | J24: =IF(A24="","",IF(I24="一式",1,IFERROR(INDEX(見積入力!$D$16:$D$25,MATCH(A24,見積入力!$A$16:$A$25,0)),"ID未登録"))) | K24: =IF(A24="","",IF(B24="生産原価",$B$9,E24)) | L24: =IF(見積入力!A24="","",見積入力!A24) | M24: =IF(L24="","",SUMIFS($F$16:$F$55,$A$16:$A$55,L24)) | N24: =IF(L24="","",COUNTIFS($A$16:$A$55,L24))
F25: =IF(H25="OK",ROUND(D25*K25*J25,0),"") | H25: =IF(COUNTA(A25:E25)+COUNTA(G25)+COUNTA(I25)=0,"",IF(OR(A25="",B25="",C25="",I25=""),"必須欄不足",IF(AND(A25<>"案件共通",COUNTIFS(見積入力!$A$16:$A$25,A25)<>1),"ID未登録・重複",IF(OR(AND(I25<>"数量連動",I25<>"一式"),AND(A25="案件共通",I25<>"一式")),"数量の扱い確認",IF(OR(NOT(ISNUMBER(D25)),NOT(ISNUMBER(K25)),AND(B25<>"生産原価",E25=""),D25="",NOT(ISNUMBER(J25))),"数値を入力",IF(OR(D25<0,K25<0,J25<=0),"負数・数量確認","OK")))))) | J25: =IF(A25="","",IF(I25="一式",1,IFERROR(INDEX(見積入力!$D$16:$D$25,MATCH(A25,見積入力!$A$16:$A$25,0)),"ID未登録"))) | K25: =IF(A25="","",IF(B25="生産原価",$B$9,E25)) | L25: =IF(見積入力!A25="","",見積入力!A25) | M25: =IF(L25="","",SUMIFS($F$16:$F$55,$A$16:$A$55,L25)) | N25: =IF(L25="","",COUNTIFS($A$16:$A$55,L25))
F26: =IF(H26="OK",ROUND(D26*K26*J26,0),"") | H26: =IF(COUNTA(A26:E26)+COUNTA(G26)+COUNTA(I26)=0,"",IF(OR(A26="",B26="",C26="",I26=""),"必須欄不足",IF(AND(A26<>"案件共通",COUNTIFS(見積入力!$A$16:$A$25,A26)<>1),"ID未登録・重複",IF(OR(AND(I26<>"数量連動",I26<>"一式"),AND(A26="案件共通",I26<>"一式")),"数量の扱い確認",IF(OR(NOT(ISNUMBER(D26)),NOT(ISNUMBER(K26)),AND(B26<>"生産原価",E26=""),D26="",NOT(ISNUMBER(J26))),"数値を入力",IF(OR(D26<0,K26<0,J26<=0),"負数・数量確認","OK")))))) | J26: =IF(A26="","",IF(I26="一式",1,IFERROR(INDEX(見積入力!$D$16:$D$25,MATCH(A26,見積入力!$A$16:$A$25,0)),"ID未登録"))) | K26: =IF(A26="","",IF(B26="生産原価",$B$9,E26))
F27: =IF(H27="OK",ROUND(D27*K27*J27,0),"") | H27: =IF(COUNTA(A27:E27)+COUNTA(G27)+COUNTA(I27)=0,"",IF(OR(A27="",B27="",C27="",I27=""),"必須欄不足",IF(AND(A27<>"案件共通",COUNTIFS(見積入力!$A$16:$A$25,A27)<>1),"ID未登録・重複",IF(OR(AND(I27<>"数量連動",I27<>"一式"),AND(A27="案件共通",I27<>"一式")),"数量の扱い確認",IF(OR(NOT(ISNUMBER(D27)),NOT(ISNUMBER(K27)),AND(B27<>"生産原価",E27=""),D27="",NOT(ISNUMBER(J27))),"数値を入力",IF(OR(D27<0,K27<0,J27<=0),"負数・数量確認","OK")))))) | J27: =IF(A27="","",IF(I27="一式",1,IFERROR(INDEX(見積入力!$D$16:$D$25,MATCH(A27,見積入力!$A$16:$A$25,0)),"ID未登録"))) | K27: =IF(A27="","",IF(B27="生産原価",$B$9,E27))
F28: =IF(H28="OK",ROUND(D28*K28*J28,0),"") | H28: =IF(COUNTA(A28:E28)+COUNTA(G28)+COUNTA(I28)=0,"",IF(OR(A28="",B28="",C28="",I28=""),"必須欄不足",IF(AND(A28<>"案件共通",COUNTIFS(見積入力!$A$16:$A$25,A28)<>1),"ID未登録・重複",IF(OR(AND(I28<>"数量連動",I28<>"一式"),AND(A28="案件共通",I28<>"一式")),"数量の扱い確認",IF(OR(NOT(ISNUMBER(D28)),NOT(ISNUMBER(K28)),AND(B28<>"生産原価",E28=""),D28="",NOT(ISNUMBER(J28))),"数値を入力",IF(OR(D28<0,K28<0,J28<=0),"負数・数量確認","OK")))))) | J28: =IF(A28="","",IF(I28="一式",1,IFERROR(INDEX(見積入力!$D$16:$D$25,MATCH(A28,見積入力!$A$16:$A$25,0)),"ID未登録"))) | K28: =IF(A28="","",IF(B28="生産原価",$B$9,E28))
F29: =IF(H29="OK",ROUND(D29*K29*J29,0),"") | H29: =IF(COUNTA(A29:E29)+COUNTA(G29)+COUNTA(I29)=0,"",IF(OR(A29="",B29="",C29="",I29=""),"必須欄不足",IF(AND(A29<>"案件共通",COUNTIFS(見積入力!$A$16:$A$25,A29)<>1),"ID未登録・重複",IF(OR(AND(I29<>"数量連動",I29<>"一式"),AND(A29="案件共通",I29<>"一式")),"数量の扱い確認",IF(OR(NOT(ISNUMBER(D29)),NOT(ISNUMBER(K29)),AND(B29<>"生産原価",E29=""),D29="",NOT(ISNUMBER(J29))),"数値を入力",IF(OR(D29<0,K29<0,J29<=0),"負数・数量確認","OK")))))) | J29: =IF(A29="","",IF(I29="一式",1,IFERROR(INDEX(見積入力!$D$16:$D$25,MATCH(A29,見積入力!$A$16:$A$25,0)),"ID未登録"))) | K29: =IF(A29="","",IF(B29="生産原価",$B$9,E29))
F30: =IF(H30="OK",ROUND(D30*K30*J30,0),"") | H30: =IF(COUNTA(A30:E30)+COUNTA(G30)+COUNTA(I30)=0,"",IF(OR(A30="",B30="",C30="",I30=""),"必須欄不足",IF(AND(A30<>"案件共通",COUNTIFS(見積入力!$A$16:$A$25,A30)<>1),"ID未登録・重複",IF(OR(AND(I30<>"数量連動",I30<>"一式"),AND(A30="案件共通",I30<>"一式")),"数量の扱い確認",IF(OR(NOT(ISNUMBER(D30)),NOT(ISNUMBER(K30)),AND(B30<>"生産原価",E30=""),D30="",NOT(ISNUMBER(J30))),"数値を入力",IF(OR(D30<0,K30<0,J30<=0),"負数・数量確認","OK")))))) | J30: =IF(A30="","",IF(I30="一式",1,IFERROR(INDEX(見積入力!$D$16:$D$25,MATCH(A30,見積入力!$A$16:$A$25,0)),"ID未登録"))) | K30: =IF(A30="","",IF(B30="生産原価",$B$9,E30))
F31: =IF(H31="OK",ROUND(D31*K31*J31,0),"") | H31: =IF(COUNTA(A31:E31)+COUNTA(G31)+COUNTA(I31)=0,"",IF(OR(A31="",B31="",C31="",I31=""),"必須欄不足",IF(AND(A31<>"案件共通",COUNTIFS(見積入力!$A$16:$A$25,A31)<>1),"ID未登録・重複",IF(OR(AND(I31<>"数量連動",I31<>"一式"),AND(A31="案件共通",I31<>"一式")),"数量の扱い確認",IF(OR(NOT(ISNUMBER(D31)),NOT(ISNUMBER(K31)),AND(B31<>"生産原価",E31=""),D31="",NOT(ISNUMBER(J31))),"数値を入力",IF(OR(D31<0,K31<0,J31<=0),"負数・数量確認","OK")))))) | J31: =IF(A31="","",IF(I31="一式",1,IFERROR(INDEX(見積入力!$D$16:$D$25,MATCH(A31,見積入力!$A$16:$A$25,0)),"ID未登録"))) | K31: =IF(A31="","",IF(B31="生産原価",$B$9,E31))
F32: =IF(H32="OK",ROUND(D32*K32*J32,0),"") | H32: =IF(COUNTA(A32:E32)+COUNTA(G32)+COUNTA(I32)=0,"",IF(OR(A32="",B32="",C32="",I32=""),"必須欄不足",IF(AND(A32<>"案件共通",COUNTIFS(見積入力!$A$16:$A$25,A32)<>1),"ID未登録・重複",IF(OR(AND(I32<>"数量連動",I32<>"一式"),AND(A32="案件共通",I32<>"一式")),"数量の扱い確認",IF(OR(NOT(ISNUMBER(D32)),NOT(ISNUMBER(K32)),AND(B32<>"生産原価",E32=""),D32="",NOT(ISNUMBER(J32))),"数値を入力",IF(OR(D32<0,K32<0,J32<=0),"負数・数量確認","OK")))))) | J32: =IF(A32="","",IF(I32="一式",1,IFERROR(INDEX(見積入力!$D$16:$D$25,MATCH(A32,見積入力!$A$16:$A$25,0)),"ID未登録"))) | K32: =IF(A32="","",IF(B32="生産原価",$B$9,E32))
F33: =IF(H33="OK",ROUND(D33*K33*J33,0),"") | H33: =IF(COUNTA(A33:E33)+COUNTA(G33)+COUNTA(I33)=0,"",IF(OR(A33="",B33="",C33="",I33=""),"必須欄不足",IF(AND(A33<>"案件共通",COUNTIFS(見積入力!$A$16:$A$25,A33)<>1),"ID未登録・重複",IF(OR(AND(I33<>"数量連動",I33<>"一式"),AND(A33="案件共通",I33<>"一式")),"数量の扱い確認",IF(OR(NOT(ISNUMBER(D33)),NOT(ISNUMBER(K33)),AND(B33<>"生産原価",E33=""),D33="",NOT(ISNUMBER(J33))),"数値を入力",IF(OR(D33<0,K33<0,J33<=0),"負数・数量確認","OK")))))) | J33: =IF(A33="","",IF(I33="一式",1,IFERROR(INDEX(見積入力!$D$16:$D$25,MATCH(A33,見積入力!$A$16:$A$25,0)),"ID未登録"))) | K33: =IF(A33="","",IF(B33="生産原価",$B$9,E33))
F34: =IF(H34="OK",ROUND(D34*K34*J34,0),"") | H34: =IF(COUNTA(A34:E34)+COUNTA(G34)+COUNTA(I34)=0,"",IF(OR(A34="",B34="",C34="",I34=""),"必須欄不足",IF(AND(A34<>"案件共通",COUNTIFS(見積入力!$A$16:$A$25,A34)<>1),"ID未登録・重複",IF(OR(AND(I34<>"数量連動",I34<>"一式"),AND(A34="案件共通",I34<>"一式")),"数量の扱い確認",IF(OR(NOT(ISNUMBER(D34)),NOT(ISNUMBER(K34)),AND(B34<>"生産原価",E34=""),D34="",NOT(ISNUMBER(J34))),"数値を入力",IF(OR(D34<0,K34<0,J34<=0),"負数・数量確認","OK")))))) | J34: =IF(A34="","",IF(I34="一式",1,IFERROR(INDEX(見積入力!$D$16:$D$25,MATCH(A34,見積入力!$A$16:$A$25,0)),"ID未登録"))) | K34: =IF(A34="","",IF(B34="生産原価",$B$9,E34))
F35: =IF(H35="OK",ROUND(D35*K35*J35,0),"") | H35: =IF(COUNTA(A35:E35)+COUNTA(G35)+COUNTA(I35)=0,"",IF(OR(A35="",B35="",C35="",I35=""),"必須欄不足",IF(AND(A35<>"案件共通",COUNTIFS(見積入力!$A$16:$A$25,A35)<>1),"ID未登録・重複",IF(OR(AND(I35<>"数量連動",I35<>"一式"),AND(A35="案件共通",I35<>"一式")),"数量の扱い確認",IF(OR(NOT(ISNUMBER(D35)),NOT(ISNUMBER(K35)),AND(B35<>"生産原価",E35=""),D35="",NOT(ISNUMBER(J35))),"数値を入力",IF(OR(D35<0,K35<0,J35<=0),"負数・数量確認","OK")))))) | J35: =IF(A35="","",IF(I35="一式",1,IFERROR(INDEX(見積入力!$D$16:$D$25,MATCH(A35,見積入力!$A$16:$A$25,0)),"ID未登録"))) | K35: =IF(A35="","",IF(B35="生産原価",$B$9,E35))
F36: =IF(H36="OK",ROUND(D36*K36*J36,0),"") | H36: =IF(COUNTA(A36:E36)+COUNTA(G36)+COUNTA(I36)=0,"",IF(OR(A36="",B36="",C36="",I36=""),"必須欄不足",IF(AND(A36<>"案件共通",COUNTIFS(見積入力!$A$16:$A$25,A36)<>1),"ID未登録・重複",IF(OR(AND(I36<>"数量連動",I36<>"一式"),AND(A36="案件共通",I36<>"一式")),"数量の扱い確認",IF(OR(NOT(ISNUMBER(D36)),NOT(ISNUMBER(K36)),AND(B36<>"生産原価",E36=""),D36="",NOT(ISNUMBER(J36))),"数値を入力",IF(OR(D36<0,K36<0,J36<=0),"負数・数量確認","OK")))))) | J36: =IF(A36="","",IF(I36="一式",1,IFERROR(INDEX(見積入力!$D$16:$D$25,MATCH(A36,見積入力!$A$16:$A$25,0)),"ID未登録"))) | K36: =IF(A36="","",IF(B36="生産原価",$B$9,E36))
F37: =IF(H37="OK",ROUND(D37*K37*J37,0),"") | H37: =IF(COUNTA(A37:E37)+COUNTA(G37)+COUNTA(I37)=0,"",IF(OR(A37="",B37="",C37="",I37=""),"必須欄不足",IF(AND(A37<>"案件共通",COUNTIFS(見積入力!$A$16:$A$25,A37)<>1),"ID未登録・重複",IF(OR(AND(I37<>"数量連動",I37<>"一式"),AND(A37="案件共通",I37<>"一式")),"数量の扱い確認",IF(OR(NOT(ISNUMBER(D37)),NOT(ISNUMBER(K37)),AND(B37<>"生産原価",E37=""),D37="",NOT(ISNUMBER(J37))),"数値を入力",IF(OR(D37<0,K37<0,J37<=0),"負数・数量確認","OK")))))) | J37: =IF(A37="","",IF(I37="一式",1,IFERROR(INDEX(見積入力!$D$16:$D$25,MATCH(A37,見積入力!$A$16:$A$25,0)),"ID未登録"))) | K37: =IF(A37="","",IF(B37="生産原価",$B$9,E37))
... F55: =IF(H55="OK",ROUND(D55*K55*J55,0),"") | H55: =IF(COUNTA(A55:E55)+COUNTA(G55)+COUNTA(I55)=0,"",IF(OR(A55="",B55="",C55="",I55=""),"必須欄不足",IF(AND(A55<>"案件共通",COUNTIFS(見積入力!$A$16:$A$25,A55)<>1),"ID未登録・重複",IF(OR(AND(I55<>"数量連動",I55<>"一式"),AND(A55="案件共通",I55<>"一式")),"数量の扱い確認",IF(OR(NOT(ISNUMBER(D55)),NOT(ISNUMBER(K55)),AND(B55<>"生産原価",E55=""),D55="",NOT(ISNUMBER(J55))),"数値を入力",IF(OR(D55<0,K55<0,J55<=0),"負数・数量確認","OK")))))) | J55: =IF(A55="","",IF(I55="一式",1,IFERROR(INDEX(見積入力!$D$16:$D$25,MATCH(A55,見積入力!$A$16:$A$25,0)),"ID未登録"))) | K55: =IF(A55="","",IF(B55="生産原価",$B$9,E55))

Sheet 設定
A2: 設定
A5: 業種 | B5: 原価シート名
A6: 木工所 | B6: 原価(木工所)
A7: 農家 | B7: 原価(農家)
A11: 自社名 | B11: サンプル事業者
A12: 住所 | B12: 住所を入力してください
A13: 連絡先 | B13: 連絡先を入力してください
A14: 担当者 | B14: 担当者名
A17: 業種を減らす場合：残す業種を選択 → この表の不要行を行ごと削除 → 不要な原価シートを削除。
A19: 業種を減らす場合は不要な登録行を行ごと削除。シート保護・数式ロックは解除済みです。

Sheet サンプル・入力例
A2: サンプル・入力例
A4: 架空の記入例です。相場ではありません。このシートの数値は実際の見積に集計されません。
A6: 木工所の販売例 | B6: 品名 | C6: 仕様 | D6: 数量 | E6: 単位 | F6: 税抜単価 | G6: 税率
A7: M001 | B7: テーブル | C7: 標準仕様 | D7: 2 | E7: 台 | F7: 50000 | G7: 0.1
A8: M002 | B8: 椅子 | C8: 標準仕様 | D8: 4 | E8: 脚 | F8: 15000 | G8: 0.1
A11: 対象ID | B11: 区分 | C11: 内容 | D11: 使用量 | E11: 原価単価 | F11: 根拠 | G11: 数量の扱い
A12: M001 | B12: 材料 | C12: テーブル材料 | D12: 1 | E12: 15000 | F12: 台当たり | G12: 数量連動
A13: M001 | B13: 作業 | C13: テーブル作業 | D13: 10 | E13: 1000 | F13: 時間/台 | G13: 数量連動
A14: M002 | B14: 材料 | C14: 椅子材料 | D14: 1 | E14: 5000 | F14: 脚当たり | G14: 数量連動
A15: M002 | B15: 作業 | C15: 椅子作業 | D15: 2.5 | E15: 1000 | F15: 時間/脚 | G15: 数量連動
A16: 案件共通 | B16: 配送 | C16: 一括配送 | D16: 1 | E16: 8000 | F16: 納品1回 | G16: 一式
A18: 木工所：売上160,000円、原価88,000円、利益72,000円、利益率45.0%。
A21: 農家の販売例 | B21: 品名 | C21: 仕様 | D21: 数量 | E21: 単位 | F21: 税抜単価 | G21: 税率
A22: M001 | B22: 野菜5kg箱 | C22: 同一作物・同一品質 | D22: 100 | E22: 箱 | F22: 2000 | G22: 0.08
A25: 対象ID | B25: 区分 | C25: 内容 | D25: 使用量 | E25: 原価単価 | F25: 根拠 | G25: 数量の扱い
A26: M001 | B26: 生産原価 | C26: 対象出荷分の生産原価 | D26: 5 | E26: 200 | F26: kg/箱・単価自動 | G26: 数量連動
A27: M001 | B27: 材料 | C27: 箱・包装材 | D27: 1 | E27: 150 | F27: 箱当たり | G27: 数量連動
A28: M001 | B28: 作業 | C28: 選別・梱包 | D28: 0.1 | E28: 1500 | F28: 時間/箱 | G28: 数量連動
A29: 案件共通 | B29: 配送 | C29: 今回の配送 | D29: 1 | E29: 10000 | F29: 出荷1回 | G29: 一式
A31: 農家：生産費用1,000,000円 ÷ 販売可能収穫量5,000kg ＝ 200円/kg。
A33: 100箱×5kg。売上200,000円、原価140,000円、利益60,000円、利益率30.0%。
A35: 農家を試す：業種を農家に変更し、見積入力A16:G25を消去してA22:G22の値をA16:G16に貼り付け。
A37: 原価側は両業種とも記入例を入力済み。実案件では入力欄を置き換え、不要行は入力セルだけ消去してください。

Sheet 計算
A2: 計算
A4: 参照シート名 | B4: =IFERROR(INDEX(設定!$B$6:$B$7,MATCH(採算シミュレーション!B5,設定!$A$6:$A$7,0)),"業種未登録") -> 原価(木工所)
A5: 出力形式 | B5: =IFERROR(INDIRECT("'"&$B$4&"'!L4"),"原価シートなし") -> COST-V1
A6: 原価入力状態 | B6: =IFERROR(INDIRECT("'"&$B$4&"'!M5"),"原価シートなし") -> OK
A7: 見積入力状態 | B7: =見積入力!I28 -> OK
A8: 試算条件 | B8: =IF(OR(NOT(ISNUMBER(採算シミュレーション!B7)),NOT(ISNUMBER(採算シミュレーション!B9)),NOT(ISNUMBER(採算シミュレーション!B11))),"試算条件は数値",IF(OR(採算シミュレーション!B7<0,採算シミュレーション!B7>=1,採算シミュレーション!B9<0,採算シミュレーション!B9>100,MOD(採算シミュレーション!B9,1)<>0,採算シミュレーション!B11< -1,採算シミュレーション!B11>10),"試算条件の範囲確認","OK")) -> OK
A9: 案件共通費 | B9: =IFERROR(INDIRECT("'"&$B$4&"'!M6"),"取得不可") -> 8000
A10: 総合状態 | B10: =IF(B5<>"COST-V1",B5,IF(B6<>"OK",B6,IF(B7<>"OK",B7,IF(B8<>"OK",B8,IF(COUNTIFS(J16:J25,"原価の紐付け不足")>0,"商品に原価未登録","OK"))))) -> OK
A11: 共通経費 | B11: =IFERROR(INDIRECT("'"&$B$4&"'!M7"),"取得不可") -> 今回は未算入
A12: 税抜小計 | B12: =IF(B7="OK",見積入力!H29,"") -> 160000
A15: 明細ID | B15: 品名 | C15: 基準売上 | D15: 原価 | E15: 原価件数 | F15: 試算売上 | G15: 試算原価 | H15: 確定売上 | I15: 税率 | J15: 紐付け
A16: =IF(見積入力!A16="","",見積入力!A16) -> M001 | B16: =IF(A16="","",見積入力!B16) -> テーブル | C16: =IF(A16="","",見積入力!H16) -> 100000 | D16: =IF(A16="","",IFERROR(INDIRECT("'"&$B$4&"'!M16"),"取得不可")) -> 50000 | E16: =IF(A16="","",IFERROR(INDIRECT("'"&$B$4&"'!N16"),"取得不可")) -> 2 | F16: =IF(OR(A16="",$B$10<>"OK"),"",ROUND(C16*(1-採算シミュレーション!$B$9/100),0)) -> 100000 | G16: =IF(OR(A16="",$B$10<>"OK"),"",ROUND(D16*(1+採算シミュレーション!$B$11),0)) -> 50000 | H16: =IF(OR(A16="",$B$10<>"OK"),"",ROUND(C16*(1-見積入力!$B$8),0)) -> 100000 | I16: =IF(A16="","",見積入力!G16) -> 0.1 | J16: =IF(A16="","",IF(AND(ISNUMBER(D16),ISNUMBER(E16),E16>0),"OK","原価の紐付け不足")) -> OK
A17: =IF(見積入力!A17="","",見積入力!A17) -> M002 | B17: =IF(A17="","",見積入力!B17) -> 椅子 | C17: =IF(A17="","",見積入力!H17) -> 60000 | D17: =IF(A17="","",IFERROR(INDIRECT("'"&$B$4&"'!M17"),"取得不可")) -> 30000 | E17: =IF(A17="","",IFERROR(INDIRECT("'"&$B$4&"'!N17"),"取得不可")) -> 2 | F17: =IF(OR(A17="",$B$10<>"OK"),"",ROUND(C17*(1-採算シミュレーション!$B$9/100),0)) -> 60000 | G17: =IF(OR(A17="",$B$10<>"OK"),"",ROUND(D17*(1+採算シミュレーション!$B$11),0)) -> 30000 | H17: =IF(OR(A17="",$B$10<>"OK"),"",ROUND(C17*(1-見積入力!$B$8),0)) -> 60000 | I17: =IF(A17="","",見積入力!G17) -> 0.1 | J17: =IF(A17="","",IF(AND(ISNUMBER(D17),ISNUMBER(E17),E17>0),"OK","原価の紐付け不足")) -> OK
A18: =IF(見積入力!A18="","",見積入力!A18) | B18: =IF(A18="","",見積入力!B18) | C18: =IF(A18="","",見積入力!H18) | D18: =IF(A18="","",IFERROR(INDIRECT("'"&$B$4&"'!M18"),"取得不可")) | E18: =IF(A18="","",IFERROR(INDIRECT("'"&$B$4&"'!N18"),"取得不可")) | F18: =IF(OR(A18="",$B$10<>"OK"),"",ROUND(C18*(1-採算シミュレーション!$B$9/100),0)) | G18: =IF(OR(A18="",$B$10<>"OK"),"",ROUND(D18*(1+採算シミュレーション!$B$11),0)) | H18: =IF(OR(A18="",$B$10<>"OK"),"",ROUND(C18*(1-見積入力!$B$8),0)) | I18: =IF(A18="","",見積入力!G18) | J18: =IF(A18="","",IF(AND(ISNUMBER(D18),ISNUMBER(E18),E18>0),"OK","原価の紐付け不足"))
A19: =IF(見積入力!A19="","",見積入力!A19) | B19: =IF(A19="","",見積入力!B19) | C19: =IF(A19="","",見積入力!H19) | D19: =IF(A19="","",IFERROR(INDIRECT("'"&$B$4&"'!M19"),"取得不可")) | E19: =IF(A19="","",IFERROR(INDIRECT("'"&$B$4&"'!N19"),"取得不可")) | F19: =IF(OR(A19="",$B$10<>"OK"),"",ROUND(C19*(1-採算シミュレーション!$B$9/100),0)) | G19: =IF(OR(A19="",$B$10<>"OK"),"",ROUND(D19*(1+採算シミュレーション!$B$11),0)) | H19: =IF(OR(A19="",$B$10<>"OK"),"",ROUND(C19*(1-見積入力!$B$8),0)) | I19: =IF(A19="","",見積入力!G19) | J19: =IF(A19="","",IF(AND(ISNUMBER(D19),ISNUMBER(E19),E19>0),"OK","原価の紐付け不足"))
A20: =IF(見積入力!A20="","",見積入力!A20) | B20: =IF(A20="","",見積入力!B20) | C20: =IF(A20="","",見積入力!H20) | D20: =IF(A20="","",IFERROR(INDIRECT("'"&$B$4&"'!M20"),"取得不可")) | E20: =IF(A20="","",IFERROR(INDIRECT("'"&$B$4&"'!N20"),"取得不可")) | F20: =IF(OR(A20="",$B$10<>"OK"),"",ROUND(C20*(1-採算シミュレーション!$B$9/100),0)) | G20: =IF(OR(A20="",$B$10<>"OK"),"",ROUND(D20*(1+採算シミュレーション!$B$11),0)) | H20: =IF(OR(A20="",$B$10<>"OK"),"",ROUND(C20*(1-見積入力!$B$8),0)) | I20: =IF(A20="","",見積入力!G20) | J20: =IF(A20="","",IF(AND(ISNUMBER(D20),ISNUMBER(E20),E20>0),"OK","原価の紐付け不足"))
A21: =IF(見積入力!A21="","",見積入力!A21) | B21: =IF(A21="","",見積入力!B21) | C21: =IF(A21="","",見積入力!H21) | D21: =IF(A21="","",IFERROR(INDIRECT("'"&$B$4&"'!M21"),"取得不可")) | E21: =IF(A21="","",IFERROR(INDIRECT("'"&$B$4&"'!N21"),"取得不可")) | F21: =IF(OR(A21="",$B$10<>"OK"),"",ROUND(C21*(1-採算シミュレーション!$B$9/100),0)) | G21: =IF(OR(A21="",$B$10<>"OK"),"",ROUND(D21*(1+採算シミュレーション!$B$11),0)) | H21: =IF(OR(A21="",$B$10<>"OK"),"",ROUND(C21*(1-見積入力!$B$8),0)) | I21: =IF(A21="","",見積入力!G21) | J21: =IF(A21="","",IF(AND(ISNUMBER(D21),ISNUMBER(E21),E21>0),"OK","原価の紐付け不足"))
A22: =IF(見積入力!A22="","",見積入力!A22) | B22: =IF(A22="","",見積入力!B22) | C22: =IF(A22="","",見積入力!H22) | D22: =IF(A22="","",IFERROR(INDIRECT("'"&$B$4&"'!M22"),"取得不可")) | E22: =IF(A22="","",IFERROR(INDIRECT("'"&$B$4&"'!N22"),"取得不可")) | F22: =IF(OR(A22="",$B$10<>"OK"),"",ROUND(C22*(1-採算シミュレーション!$B$9/100),0)) | G22: =IF(OR(A22="",$B$10<>"OK"),"",ROUND(D22*(1+採算シミュレーション!$B$11),0)) | H22: =IF(OR(A22="",$B$10<>"OK"),"",ROUND(C22*(1-見積入力!$B$8),0)) | I22: =IF(A22="","",見積入力!G22) | J22: =IF(A22="","",IF(AND(ISNUMBER(D22),ISNUMBER(E22),E22>0),"OK","原価の紐付け不足"))
A23: =IF(見積入力!A23="","",見積入力!A23) | B23: =IF(A23="","",見積入力!B23) | C23: =IF(A23="","",見積入力!H23) | D23: =IF(A23="","",IFERROR(INDIRECT("'"&$B$4&"'!M23"),"取得不可")) | E23: =IF(A23="","",IFERROR(INDIRECT("'"&$B$4&"'!N23"),"取得不可")) | F23: =IF(OR(A23="",$B$10<>"OK"),"",ROUND(C23*(1-採算シミュレーション!$B$9/100),0)) | G23: =IF(OR(A23="",$B$10<>"OK"),"",ROUND(D23*(1+採算シミュレーション!$B$11),0)) | H23: =IF(OR(A23="",$B$10<>"OK"),"",ROUND(C23*(1-見積入力!$B$8),0)) | I23: =IF(A23="","",見積入力!G23) | J23: =IF(A23="","",IF(AND(ISNUMBER(D23),ISNUMBER(E23),E23>0),"OK","原価の紐付け不足"))
A24: =IF(見積入力!A24="","",見積入力!A24) | B24: =IF(A24="","",見積入力!B24) | C24: =IF(A24="","",見積入力!H24) | D24: =IF(A24="","",IFERROR(INDIRECT("'"&$B$4&"'!M24"),"取得不可")) | E24: =IF(A24="","",IFERROR(INDIRECT("'"&$B$4&"'!N24"),"取得不可")) | F24: =IF(OR(A24="",$B$10<>"OK"),"",ROUND(C24*(1-採算シミュレーション!$B$9/100),0)) | G24: =IF(OR(A24="",$B$10<>"OK"),"",ROUND(D24*(1+採算シミュレーション!$B$11),0)) | H24: =IF(OR(A24="",$B$10<>"OK"),"",ROUND(C24*(1-見積入力!$B$8),0)) | I24: =IF(A24="","",見積入力!G24) | J24: =IF(A24="","",IF(AND(ISNUMBER(D24),ISNUMBER(E24),E24>0),"OK","原価の紐付け不足"))
A25: =IF(見積入力!A25="","",見積入力!A25) | B25: =IF(A25="","",見積入力!B25) | C25: =IF(A25="","",見積入力!H25) | D25: =IF(A25="","",IFERROR(INDIRECT("'"&$B$4&"'!M25"),"取得不可")) | E25: =IF(A25="","",IFERROR(INDIRECT("'"&$B$4&"'!N25"),"取得不可")) | F25: =IF(OR(A25="",$B$10<>"OK"),"",ROUND(C25*(1-採算シミュレーション!$B$9/100),0)) | G25: =IF(OR(A25="",$B$10<>"OK"),"",ROUND(D25*(1+採算シミュレーション!$B$11),0)) | H25: =IF(OR(A25="",$B$10<>"OK"),"",ROUND(C25*(1-見積入力!$B$8),0)) | I25: =IF(A25="","",見積入力!G25) | J25: =IF(A25="","",IF(AND(ISNUMBER(D25),ISNUMBER(E25),E25>0),"OK","原価の紐付け不足"))
A29: 基準原価 | B29: =IF(B10="OK",SUM(D16:D25)+B9,"") -> 88000 | L29: 項目 | M29: 基準 | N29: 試算
A30: 試算売上 | B30: =IF(B10="OK",SUM(F16:F25),"") -> 160000 | L30: 売上 | M30: =B12 -> 160000 | N30: =B30 -> 160000
A31: 試算原価 | B31: =IF(B10="OK",SUM(G16:G25)+B41,"") -> 88000 | L31: 原価 | M31: =B29 -> 88000 | N31: =B31 -> 88000
A32: 予定案件利益 | B32: =IF(B10="OK",B30-B31,"") -> 72000 | L32: 利益 | M32: =B40 -> 72000 | N32: =B32 -> 72000
A33: 予定案件利益率 | B33: =IF(B10="OK",IF(B30=0,"算出不可",B32/B30),"") -> 0.45
A34: 目標必要売価 | B34: =IF(B10="OK",ROUNDUP(B31/(1-採算シミュレーション!B7),0),"") -> 125715
A35: 目標維持値引上限 | B35: =IF(B10="OK",IF(B12=0,"算出不可",IF(B34>B12,"値上げが必要",1-B34/B12)),"") -> 0.21428125 | L35: 値引率 | M35: 利益(円)
A36: 確定売上 | B36: =IF(B10="OK",SUM(H16:H25),"") -> 160000 | L36: 0% | M36: =IF(B10="OK",B12*(1-0)-B31,"") -> 72000
A37: 10%税額 | B37: =IF(B10="OK",ROUNDDOWN(SUMIFS(H16:H25,I16:I25,0.1)*0.1,0),"") -> 16000 | L37: 5% | M37: =IF(B10="OK",B12*(1-0.05)-B31,"") -> 64000
A38: 8%税額 | B38: =IF(B10="OK",ROUNDDOWN(SUMIFS(H16:H25,I16:I25,0.08)*0.08,0),"") -> 0 | L38: 10% | M38: =IF(B10="OK",B12*(1-0.1)-B31,"") -> 56000
A39: 税込見積額 | B39: =IF(B10="OK",B36+B37+B38,"") -> 176000 | L39: 15% | M39: =IF(B10="OK",B12*(1-0.15)-B31,"") -> 48000
A40: 基準利益 | B40: =IF(B10="OK",B12-B29,"") -> 72000 | L40: 20% | M40: =IF(B10="OK",B12*(1-0.2)-B31,"") -> 40000
A41: 試算共通費 | B41: =IF(B10="OK",ROUND(B9*(1+採算シミュレーション!B11),0),"") -> 8000 | L41: 25% | M41: =IF(B10="OK",B12*(1-0.25)-B31,"") -> 32000
L42: 30% | M42: =IF(B10="OK",B12*(1-0.3)-B31,"") -> 24000
L43: 35% | M43: =IF(B10="OK",B12*(1-0.35)-B31,"") -> 16000
L44: 40% | M44: =IF(B10="OK",B12*(1-0.4)-B31,"") -> 8000
L45: 45% | M45: =IF(B10="OK",B12*(1-0.45)-B31,"") -> 0
L46: 50% | M46: =IF(B10="OK",B12*(1-0.5)-B31,"") -> -8000

Sheet 使い方・検証
A2: 使い方・検証
A4: v0.2 デザイン・売上分析評価用。Windows版Excelでの操作・保存・印刷は未検証です。
A6: 1. 採算シミュレーションで業種を選び、見積入力に販売明細を入力します。
A8: 2. 対象の原価シートに原価を入力します。商品ごとに少なくとも1行の原価が必要です。
A10: 3. 値引率・原価増減率を変更し、利益を確認します。見積書は確定値引率だけを使用します。
A12: 4. 見積書の宛先・発行日・税区分を確認し、Excelの印刷／PDF保存で出力します。
A14: 淡い緑色が入力欄。全シートの固定・保護・数式ロックを解除済み。数式の上書きにご注意ください。
A16: 上限：販売10明細、原価40明細/業種。行追加・削除ではなく、用意した入力欄を使用してください。
A18: 案件共通費は商品へ自動配賦しません。商品別差額は案件共通費控除前、案件利益は控除後です。
A20: 数量連動は一定の使用量・単価を仮定します。数量変更後は歩留まり・段取り・配送条件を再確認してください。
A22: 農業原価は1作物・1栽培単位の平均原価。等級別原価・複数作物・仕掛品・在庫管理は対象外です。
A24: 生産費用には栽培・収穫まで、出荷費用には選別・梱包・配送を計上する例です。重複計上に注意。
... A42: 下記互換性表は仕様の確認範囲。最古の動作保証バージョンは実機検証後に確定します。
A46: 機能 | B46: 仕様確認範囲 | C46: 実機確認 | D46: 最古の保証版
A47: IF/SUMIFS/INDEX/MATCH等 | B47: 2016以降の公式資料を参照 | C47: 未実施 | D47: 未確定
A48: INDIRECTによる切替 | B48: 2016以降の公式資料を参照 | C48: 未実施 | D48: 未確定
A49: 標準グラフ・入力規則 | B49: 対象Excelごとに要確認 | C49: 未実施 | D49: 未確定
A50: スクロールバー | B50: VML組込・操作は未検証 | C50: 未実施 | D50: 未確定
A51: 印刷・PDF保存 | B51: 対象Excelごとに要確認 | C51: 未実施 | D51: 未確定
A54: 参考：https://support.microsoft.com/en-us/excel/functions/indirect-function
A56: 参考：https://support.microsoft.com/en-us/excel/add-a-scroll-bar-or-spin-button-to-a-worksheet

Sheet 売上分析
A2: 売上分析 | B2: 商品と季節の動きをつかむ
A3: すべて架空の販売履歴です。現在の見積・予定案件利益には加算されません。
A6: 業種・商品スライサーとタイムラインに連動（前年比・前年比較は前年データを参照）
A8: 税抜売上（円） | D8: 計上原価控除後差額（円） | G8: 差額率 | J8: 前年比
A9: =ROUND(GETPIVOTDATA("売上合計",制御!$H$14),0) -> 47492700 | D9: =ROUND(GETPIVOTDATA("差額合計",制御!$H$14),0) -> 18852426 | G9: =IF(A9=0,"算出不可",D9/A9) -> 0.39695418 | J9: =IFERROR(GETPIVOTDATA("売上（万円）",制御!$H$20,"年",2026)/GETPIVOTDATA("売上（万円）",制御!$H$20,"年",2025)-1,"算出不可") -> -0.011131169
A11: 差額は売上履歴の計上原価のみを控除。会計上の粗利・営業利益や現在の見積利益とは区別します。
A44: 商品×月ヒートマップ（万円）
A45: 商品／年月 | B45: 2025-01 | C45: 2025-02 | D45: 2025-03 | E45: 2025-04 | F45: 2025-05 | G45: 2025-06 | H45: 2025-07 | I45: 2025-08 | J45: 2025-09 | K45: 2025-10 | L45: 2025-11 | M45: 2025-12 | N45: 2026-01 | O45: 2026-02 | P45: 2026-03 | Q45: 2026-04 | R45: 2026-05 | S45: 2026-06 | T45: 2026-07 | U45: 2026-08 | V45: 2026-09 | W45: 2026-10 | X45: 2026-11 | Y45: 2026-12 | Z45: 推移
A46: =IF(ROW()-45>COUNTA(商品マスタ!$B$5:$B$24),"",INDEX(商品マスタ!$B$5:$B$24,ROW()-45)) -> テーブル | B46: =IF($A46="","",IFERROR(ROUND(GETPIVOTDATA("売上（万円）",制御!$H$2,"商品",$A46,"年月",B$45),0),"")) | C46: =IF($A46="","",IFERROR(ROUND(GETPIVOTDATA("売上（万円）",制御!$H$2,"商品",$A46,"年月",C$45),0),"")) | D46: =IF($A46="","",IFERROR(ROUND(GETPIVOTDATA("売上（万円）",制御!$H$2,"商品",$A46,"年月",D$45),0),"")) | E46: =IF($A46="","",IFERROR(ROUND(GETPIVOTDATA("売上（万円）",制御!$H$2,"商品",$A46,"年月",E$45),0),"")) | F46: =IF($A46="","",IFERROR(ROUND(GETPIVOTDATA("売上（万円）",制御!$H$2,"商品",$A46,"年月",F$45),0),"")) | G46: =IF($A46="","",IFERROR(ROUND(GETPIVOTDATA("売上（万円）",制御!$H$2,"商品",$A46,"年月",G$45),0),"")) | H46: =IF($A46="","",IFERROR(ROUND(GETPIVOTDATA("売上（万円）",制御!$H$2,"商品",$A46,"年月",H$45),0),"")) | I46: =IF($A46="","",IFERROR(ROUND(GETPIVOTDATA("売上（万円）",制御!$H$2,"商品",$A46,"年月",I$45),0),"")) | ... Y46: =IF($A46="","",IFERROR(ROUND(GETPIVOTDATA("売上（万円）",制御!$H$2,"商品",$A46,"年月",Y$45),0),"")) -> 135
A47: =IF(ROW()-45>COUNTA(商品マスタ!$B$5:$B$24),"",INDEX(商品マスタ!$B$5:$B$24,ROW()-45)) -> 椅子 | B47: =IF($A47="","",IFERROR(ROUND(GETPIVOTDATA("売上（万円）",制御!$H$2,"商品",$A47,"年月",B$45),0),"")) | C47: =IF($A47="","",IFERROR(ROUND(GETPIVOTDATA("売上（万円）",制御!$H$2,"商品",$A47,"年月",C$45),0),"")) | D47: =IF($A47="","",IFERROR(ROUND(GETPIVOTDATA("売上（万円）",制御!$H$2,"商品",$A47,"年月",D$45),0),"")) | E47: =IF($A47="","",IFERROR(ROUND(GETPIVOTDATA("売上（万円）",制御!$H$2,"商品",$A47,"年月",E$45),0),"")) | F47: =IF($A47="","",IFERROR(ROUND(GETPIVOTDATA("売上（万円）",制御!$H$2,"商品",$A47,"年月",F$45),0),"")) | G47: =IF($A47="","",IFERROR(ROUND(GETPIVOTDATA("売上（万円）",制御!$H$2,"商品",$A47,"年月",G$45),0),"")) | H47: =IF($A47="","",IFERROR(ROUND(GETPIVOTDATA("売上（万円）",制御!$H$2,"商品",$A47,"年月",H$45),0),"")) | I47: =IF($A47="","",IFERROR(ROUND(GETPIVOTDATA("売上（万円）",制御!$H$2,"商品",$A47,"年月",I$45),0),"")) | ... Y47: =IF($A47="","",IFERROR(ROUND(GETPIVOTDATA("売上（万円）",制御!$H$2,"商品",$A47,"年月",Y$45),0),"")) -> 54
A48: =IF(ROW()-45>COUNTA(商品マスタ!$B$5:$B$24),"",INDEX(商品マスタ!$B$5:$B$24,ROW()-45)) -> 収納棚 | B48: =IF($A48="","",IFERROR(ROUND(GETPIVOTDATA("売上（万円）",制御!$H$2,"商品",$A48,"年月",B$45),0),"")) | C48: =IF($A48="","",IFERROR(ROUND(GETPIVOTDATA("売上（万円）",制御!$H$2,"商品",$A48,"年月",C$45),0),"")) | D48: =IF($A48="","",IFERROR(ROUND(GETPIVOTDATA("売上（万円）",制御!$H$2,"商品",$A48,"年月",D$45),0),"")) | E48: =IF($A48="","",IFERROR(ROUND(GETPIVOTDATA("売上（万円）",制御!$H$2,"商品",$A48,"年月",E$45),0),"")) | F48: =IF($A48="","",IFERROR(ROUND(GETPIVOTDATA("売上（万円）",制御!$H$2,"商品",$A48,"年月",F$45),0),"")) | G48: =IF($A48="","",IFERROR(ROUND(GETPIVOTDATA("売上（万円）",制御!$H$2,"商品",$A48,"年月",G$45),0),"")) | H48: =IF($A48="","",IFERROR(ROUND(GETPIVOTDATA("売上（万円）",制御!$H$2,"商品",$A48,"年月",H$45),0),"")) | I48: =IF($A48="","",IFERROR(ROUND(GETPIVOTDATA("売上（万円）",制御!$H$2,"商品",$A48,"年月",I$45),0),"")) | ... Y48: =IF($A48="","",IFERROR(ROUND(GETPIVOTDATA("売上（万円）",制御!$H$2,"商品",$A48,"年月",Y$45),0),"")) -> 98
